Workbook

Sheet Executive Summary (GDT Project)
A1: EXECUTIVE SUMMARY - MRS PATHFINDER GDT RAILCAR PROPOSAL
A2: Exchange Rate: | B2: USD 1.00 = BRL 5.16
A3: Profit Margin (%): | B3: 0.45 | C3: <- editable input. Change this to update the sale price table below.
A5: 1) COST / PURE BREAKEVEN (initial Pathfinder price, no margin)
A6: Project Module | B6: Cost BRL (Excl. Taxes) | C6: Cost USD (Excl. Taxes) | D6: Cost BRL (Incl. Taxes) | E6: Cost USD (Incl. Taxes) | F6: % of Total
A7: 1. Equipment & Components (BOM Pathfinder + SKID) | B7: =SUM('Final Cost List'!L2:L163) -> 2137279.5 | C7: 350000 | D7: =SUM('Final Cost List'!M2:M163) -> 2676282.9 | E7: =SUM('Final Cost List'!K2:K163) -> 518659.48 | F7: =B7/$B$9 -> 0.75122209
A8: 2. Adaptation, Container & Labor (Rollup GDT) | B8: =SUM('GDT Integration and Assembly'!C2:C18) -> 707790.6 | C8: =SUM('GDT Integration and Assembly'!D2:D18) -> 137168.72 | D8: =SUM('GDT Integration and Assembly'!E2:E18) -> 886289.26 | E8: =SUM('GDT Integration and Assembly'!F2:F18) -> 171761.48 | F8: =B8/$B$9 -> 0.24877791
A9: TOTAL CONSOLIDATED GDT RAILCAR PROJECT (COST) | B9: =SUM(B7:B8) -> 2845070.1 | C9: =SUM(C7:C8) -> 487168.72 | D9: =SUM(D7:D8) -> 3562572.2 | E9: =SUM(E7:E8) -> 690420.96 | F9: 1
A11: 2) SALE PRICE WITH PROFIT MARGIN (driven by cell B3)
A12: Project Module | B12: Sale Price BRL (Excl. Taxes) | C12: Sale Price USD (Excl. Taxes) | D12: Sale Price BRL (Incl. Taxes) | E12: Sale Price USD (Incl. Taxes) | F12: % of Total
A13: 1. Equipment & Components (BOM Pathfinder + SKID) | B13: =B7*(1+$B$3) -> 3099055.3 | C13: =C7*(1+$B$3) -> 507500 | D13: =D7*(1+$B$3) -> 3880610.2 | E13: =E7*(1+$B$3) -> 752056.24 | F13: =B13/$B$15 -> 0.75122209
A14: 2. Adaptation, Container & Labor (Rollup GDT) | B14: =B8*(1+$B$3) -> 1026296.4 | C14: =C8*(1+$B$3) -> 198894.65 | D14: =D8*(1+$B$3) -> 1285119.4 | E14: =E8*(1+$B$3) -> 249054.15 | F14: =B14/$B$15 -> 0.24877791
A15: TOTAL CONSOLIDATED GDT RAILCAR PROJECT (SALE PRICE) | B15: =SUM(B13:B14) -> 4125351.7 | C15: =SUM(C13:C14) -> 706394.65 | D15: =SUM(D13:D14) -> 5165729.6 | E15: =SUM(E13:E14) -> 1001110.4 | F15: 1

Sheet Final Cost List
A1: Part Number | B1: Description | C1: System | D1: SubSystem | E1: Weight (lbs) | F1: Quantity | G1: BOM Price (USD Unit) | H1: Final Unit Price USD (Excluding Taxes) | I1: Final Total Price USD (Excluding Taxes) | J1: Final Unit Price USD (Including Taxes) | K1: Final Total Price USD (Including Taxes) | L1: Total Price BRL (Excluding Taxes) | M1: Total Price BRL (Including Taxes) | N1: PAC Price (BRL Unit) | O1: BOM Price (USD Unit) | P1: Cost Source | Q1: Status / Notes | S1: Simple Item Category | T1: Nationalization Status | U1: Import Scenario (BOM+TP+Freight+Duty, BRL Incl. Tax) | V1: Nationalized/PAC Price (BRL Incl. Tax) | W1: Cheaper Option
A2: 41A296352CMP437 | B2: Dual Processor Module (DPM)+ LXA (Distributed Power Radio) | C2: Controls (MCA, train control, er etc) | D2: LXA | E2: 10 | F2: 1 | G2: 63100.819 | H2: 96312.869 | I2: 96312.869 | J2: 120602.14 | K2: 120602.14 | L2: 496974.41 | M2: 622307.04 | P2: Imported BOM (USA) | Q2: TP included; international freight updated to 9%
A3: 37495P | B3: KIT ETMS VIRGIN TRAINS FEC EVO44 | C3: PTC | D3: PTC KIT MASTER | F3: 1 | G3: 28529 | H3: 43544.757 | I3: 43544.757 | J3: 54526.368 | K3: 54526.368 | L3: 224690.95 | M3: 281356.06 | P3: Imported BOM (USA) | Q3: Direct supplier purchase; TP excluded; international freight 9%
A4: 84A222059P5 | B4: BATTERIES | C4: Power | D4: POWER | E4: 2476 | F4: 2 | G4: 15685.42 | H4: 20427.624 | I4: 40855.249 | J4: 25579.294 | K4: 51158.589 | L4: 210813.08 | M4: 263978.32 | P4: Imported BOM (USA) | Q4: TP included; international freight updated to 9%
A5: 41A296352LUG24 | B5: CSX Antenna Enclosure Arrangement | C5: Connectivity | D5: ANTENNA KIT Master | F5: 1 | G5: 30000 | H5: 39069.96 | I5: 39069.96 | J5: 48923.065 | K5: 48923.065 | L5: 201600.99 | M5: 252443.02 | P5: Imported BOM (USA) | Q5: TP included; international freight updated to 9%
A6: 84A215295P62 | B6: Pneumatic Brake Control System (Including lament and control portions) Includes EM EAB Control Functionality | C6: Air | D6: Fastbrake | E6: 296 | F6: 1 | G6: 23409.1 | H6: 35730.084 | I6: 35730.084 | J6: 44740.902 | K6: 44740.902 | L6: 184367.23 | M6: 230863.05 | P6: Imported BOM (USA) | Q6: Direct supplier purchase; TP excluded; international freight 9%
A7: 41A296352DNP37 | B7: RADIO PRAD PTC RADIO | C7: PTC | D7: PTC | E7: 21.2 | F7: 1 | G7: 20000 | H7: 26046.64 | I7: 26046.64 | J7: 32615.377 | K7: 32615.377 | L7: 134400.66 | M7: 168295.34 | P7: Imported BOM (USA) | Q7: Direct supplier purchase; TP excluded; international freight 9%
A8: 17FM878A6 | B8: NIO 2.0 | C8: Controls (MCA, train control, er etc) | D8: MCA | E8: 19 | F8: 3 | G8: 5176.9118 | H8: 6742.0579 | I8: 20226.174 | J8: 8442.3465 | K8: 25327.039 | L8: 104367.06 | M8: 130687.52 | P8: Imported BOM (USA) | Q8: TP included; international freight updated to 9%
A9: L7000083-900 | B9: Wireless Communications Management Module, Gen 3 (WCM3)​ | C9: Controls (MCA, train control, er etc) | D9: TRAIN CONTROL | E9: 5 | F9: 2 | G9: 5000 | H9: 7631.6655 | I9: 15263.331 | J9: 9556.3054 | K9: 19112.611 | L9: 78758.788 | M9: 98621.072 | P9: Imported BOM (USA) | Q9: Made by GET; retained for GET impact analysis | S9: Wire/Cable | T9: Low confidence - no comparable PAC item found | U9: 98621.072 | V9: 7609.408 | W9: PAC/National is cheaper (by R$ 91,011.66)
A10: 84A237085AEP121 | B10: 8 Slot ACC Chassis for MCA w/ i7 HPEAP and SMM2 Cards | C10: Controls (MCA, train control, er etc) | D10: TRAIN CONTROL | E10: 20 | F10: 1 | G10: 8000 | H10: 12210.665 | I10: 12210.665 | J10: 15290.089 | K10: 15290.089 | L10: 63007.031 | M10: 78896.858 | P10: Imported BOM (USA) | Q10: TP included; international freight updated to 9%
A11: 17FL472A2 | B11: TMC PANEL | C11: SKID Assembly | D11: SKID (Skid) | E11: 45 | F11: 1 | I11: 11326.967 | J11: 14183.531 | K11: 14183.531 | L11: 58447.152 | M11: 73187.017 | N11: 58447.152 | P11: PAC (Brazil BRL) | Q11: Direct supplier purchase; TP excluded; international freight 9%
A12: 17KC108E28 | B12: MASTER CONTROLLER | C12: Controls (MCA, train control, er etc) | D12: TRAIN CONTROL | E12: 57 | F12: 1 | G12: 5877.102 | I12: 9464.1997 | J12: 11850.989 | K12: 11850.989 | L12: 48835.27 | M12: 61151.102 | P12: GET | Q12: TP included; international freight updated to 9%
A13: 84A215295P73 | B13: Air Brake Handle Assembly (AAR Console) | C13: Air | D13: Fastbrake | E13: 17.5 | F13: 1 | G13: 5702.83 | H13: 8704.4182 | I13: 8704.4182 | J13: 10899.597 | K13: 10899.597 | L13: 44914.798 | M13: 56241.921 | P13: Imported BOM (USA) | Q13: Direct supplier purchase; TP excluded; international freight 9%
A14: 17FM868B2 | B14: SNIO | C14: Controls (MCA, train control, er etc) | D14: MCA | E14: 11 | F14: 1 | G14: 4150.9559 | H14: 5405.9227 | I14: 5405.9227 | J14: 6769.2496 | K14: 6769.2496 | L14: 27894.561 | M14: 34929.328 | P14: Imported BOM (USA) | Q14: Direct supplier purchase; TP excluded; international freight 9%
A15: 41A296352DNP55 | B15: VOICE RADIO RITRON | C15: Connectivity | D15: VOICE RADIO | E15: 16.7 | F15: 1 | G15: 3933 | H15: 5122.0718 | I15: 5122.0718 | J15: 6413.8139 | K15: 6413.8139 | L15: 26429.89 | M15: 33095.28 | P15: Imported BOM (USA) | Q15: TP included; international freight updated to 9%
A16: 32613P | B16: KIT ETMS AXLE INTERFACE FOR WPart Number 29266P | C16: PTC | D16: PTC | E16: 10 | F16: 1 | G16: 2981.71 | H16: 4551.0827 | I16: 4551.0827 | J16: 5698.8263 | K16: 5698.8263 | L16: 23483.587 | M16: 29405.944 | P16: Imported BOM (USA) | Q16: Direct supplier purchase; TP excluded; international freight 9%
A17: 17FH40X1 | B17: LPS 17FH40 (COMMON LOGIC POWER SUPPLY) (5v, 15v, 19v, 24v) | C17: POWER | D17: POWER SUPPLY | E17: 40 | F17: 1 | I17: 2915.0271 | J17: 3650.1717 | K17: 3650.1717 | L17: 15041.54 | M17: 18834.886 | N17: 15041.54 | P17: PAC (Brazil BRL) | Q17: Brazilian factory PAC price (local Brazilian cost)
A18: 41D758679BJG16 84D704379AFG1 | B18: EC Part NumberL ASM | C18: Power | D18: Circuit Breaker | F18: 1 | G18: 1572.36 | I18: 2532.0522 | J18: 3170.6138 | K18: 3170.6138 | L18: 13065.389 | M18: 16360.367 | P18: GET | Q18: Made by GET; retained for GET impact analysis
A19: 41B546155P2 | B19: Horn | C19: Controls (MCA, train control, er etc) | D19: TRAIN CONTROL | E19: 10 | F19: 1 | G19: 1891.99 | H19: 2463.9991 | I19: 2463.9991 | J19: 3085.3983 | K19: 3085.3983 | L19: 12714.235 | M19: 15920.655 | P19: Imported BOM (USA) | Q19: Brazilian factory PAC price (local Brazilian cost)
B20: Ditchlight Control Box (SMART BOX-V3-DLC ) | C20: Controls (MCA, train control, er etc) | D20: TRAIN CONTROL | E20: 5 | F20: 2 | G20: 800 | H20: 1221.0665 | I20: 2442.133 | J20: 1529.0089 | K20: 3058.0177 | L20: 12601.406 | M20: 15779.372 | P20: Imported BOM (USA) | Q20: Brazilian factory PAC price (local Brazilian cost)
B21: LED Ditch Light | C21: Controls (MCA, train control, er etc) | D21: TRAIN CONTROL | E21: 2 | F21: 4 | G21: 375 | H21: 572.37491 | I21: 2289.4997 | J21: 716.72291 | K21: 2866.8916 | L21: 11813.818 | M21: 14793.161 | P21: Imported BOM (USA) | Q21: TP included; international freight updated to 9%
A22: 17FM839B1 | B22: PANEL ASM CFD - Thin Client Display | C22: Controls (MCA, train control, er etc) | D22: MCA | F22: 1 | I22: 2248.7824 | J22: 2815.9058 | K22: 2815.9058 | L22: 11603.717 | M22: 14530.074 | N22: 11603.717 | P22: PAC (Brazil BRL) | Q22: Made by GET; retained for GET impact analysis
A23: 17FM839A3 | B23: TCD (Thin Client Display) | C23: SKID Assembly | D23: SKID (Skid) | F23: 1 | I23: 2248.7824 | J23: 2815.9058 | K23: 2815.9058 | L23: 11603.717 | M23: 14530.074 | N23: 11603.717 | P23: PAC (Brazil BRL) | Q23: Direct supplier purchase; TP excluded; international freight 9%
A24: 84A201003DAP1 | B24: ELECTRIC Bell | C24: Controls (MCA, train control, er etc) | D24: TRAIN CONTROL | F24: 1 | I24: 1839.4297 | J24: 2303.3179 | K24: 2303.3179 | L24: 9491.4571 | M24: 11885.12 | N24: 9491.4571 | P24: PAC (Brazil BRL) | Q24: TP included; international freight updated to 9%
A25: 17FB193E2F | B25: GET Card | C25: GET | D25: GET Card | F25: 1 | I25: 1792.8535 | J25: 2244.9956 | K25: 2244.9956 | L25: 9251.1239 | M25: 11584.177 | N25: 9251.1239 | P25: PAC (Brazil BRL) | Q25: Made by GET; retained for GET impact analysis
A26: 84A215295P3 | B26: POU-to-Handle cable 18' length | C26: Air | D26: Fastbrake | F26: 1 | G26: 1036.89 | H26: 1582.6395 | I26: 1582.6395 | J26: 1981.7675 | K26: 1981.7675 | L26: 8166.42 | M26: 10225.92 | P26: Imported BOM (USA) | Q26: TP included; international freight updated to 9% | S26: Wire/Cable | T26: Low confidence - PAC family match, different length | U26: 10225.92 | V26: 8409.4743 | W26: PAC/National is cheaper (by R$ 1,816.45)
A27: 41B566322ACG1 | B27: TRAINLINE RESISTOR PANEL | C27: SKID Assembly | D27: Controls (MCA, train control, er etc) | F27: 1 | I27: 1306.7417 | J27: 1636.2907 | K27: 1636.2907 | L27: 6742.7873 | M27: 8443.2599 | N27: 6742.7873 | P27: GET | Q27: TP included; international freight updated to 9%
A28: 41A296304DDP4 | B28: G-RECTIFIER POWER BLOCK | C28: SKID Assembly | D28: Controls (MCA, train control, er etc) | F28: 20 | I28: 1264.4303 | J28: 79.16543 | K28: 1583.3086 | L28: 6524.4601 | M28: 8169.8724 | N28: 326.22301 | P28: PAC (Brazil BRL) | Q28: Brazilian factory PAC price (local Brazilian cost)
A29: RCCR-RMTCBL-RA-CUSTOM | B29: VOICE RADIO RITRON CABLE,REMOTE,RR-225/XXX, RCCR,RIGHT ANGLE,19-PIN,FLAME RETARDANT | C29: Connectivity | D29: VOICE RADIO | F29: 1 | G29: 761 | H29: 991.07465 | I29: 991.07465 | J29: 1241.0151 | K29: 1241.0151 | L29: 5113.9452 | M29: 6403.6379 | P29: Imported BOM (USA) | Q29: Brazilian factory PAC price (local Brazilian cost) | S29: Wire/Cable | T29: Low confidence - no comparable PAC item found | U29: 6403.6379 | V29: 3569.0421 | W29: PAC/National is cheaper (by R$ 2,834.60)
A30: 41C663693G1 | B30: PANEL CPF | C30: Power | D30: POWER | F30: 1 | I30: 924.61033 | J30: 1157.789 | K30: 1157.789 | L30: 4770.9893 | M30: 5974.1915 | N30: 4770.9893 | P30: GET | Q30: Brazilian factory PAC price (local Brazilian cost)
A31: 41A296352PTP306/41A296352PTP122 | B31: Assembled Air Manifold (Contains 3 pressure sensors mounted in appropriate locations on Air Manifold.) | C31: PTC | D31: PTC | F31: 1 | G31: 595.7889 | H31: 909.37232 | I31: 909.37232 | J31: 1138.7081 | K31: 1138.7081 | L31: 4692.3612 | M31: 5875.734 | P31: Imported BOM (USA) | Q31: Brazilian factory PAC price (local Brazilian cost)
A32: 84A232147P1 | B32: KNOB HLD DWN with washer and screw | C32: Controls (MCA, train control, er etc) | D32: TRAIN CONTROL | F32: 30 | I32: 741.13821 | J32: 30.934895 | K32: 928.04685 | L32: 3824.2732 | M32: 4788.7217 | N32: 127.47577 | P32: PAC (Brazil BRL) | Q32: Brazilian factory PAC price (local Brazilian cost)
A33: 32447P | B33: ASY CABLE WHEEL TACH AC EVO/SD70 ACE | C33: PTC | D33: PTC | F33: 1 | G33: 411.22 | H33: 627.6587 | I33: 627.6587 | J33: 785.94878 | K33: 785.94878 | L33: 3238.7189 | M33: 4055.4957 | P33: Imported BOM (USA) | Q33: Calculated with TP (17.2%) + International Freight (15%) + Import Duty (16%) + Domestic Freight (3%) | Qtd=1.0 | S33: Wire/Cable | T33: High confidence PAC match (exact desc, PN 29707P) - not yet applied | U33: 4055.4957 | V33: 373.6982 | W33: PAC/National is cheaper (by R$ 3,681.80)
A34: 41A296352PTP10/319/34 | B34: VALVE Part NumberEUMATIC NC/CO (Penalty Magnet Valve) Graham-White 812-142 | C34: PTC | D34: PTC | F34: 1 | G34: 404.6239 | H34: 617.59085 | I34: 617.59085 | J34: 773.34191 | K34: 773.34191 | L34: 3186.7688 | M34: 3990.4443 | P34: Imported BOM (USA) | Q34: Brazilian factory PAC price (local Brazilian cost)
A35: 84A201176P1 | B35: Pathfinder Control Unit Connector (MU Plug) | C35: Controls (MCA, train control, er etc) | D35: TRAIN CONTROL | F35: 2 | I35: 573.97817 | J35: 359.36524 | K35: 718.73049 | L35: 2961.7273 | M35: 3708.6493 | N35: 1480.8637 | P35: PAC (Brazil BRL) | Q35: Calculated with TP (17.2%) + International Freight (15%) + Import Duty (16%) + Domestic Freight (3%) | Qtd=1.0 | S35: Connector/Plug | T35: Already nationalized (PAC) | U35: 4406.427 | V35: 3708.6493 | W35: PAC/National is cheaper (by R$ 697.78)
A36: 84A201150ACP2 | B36: CROSSING BELL PUSH BUTTON SWITCH | C36: Controls (MCA, train control, er etc) | D36: TRAIN CONTROL | F36: 1 | I36: 551.04203 | J36: 690.01005 | K36: 690.01005 | L36: 2843.3769 | M36: 3560.4519 | N36: 2843.3769 | P36: PAC (Brazil BRL) | Q36: Calculated with TP (17.2%) + International Freight (15%) + Import Duty (16%) + Domestic Freight (3%) | Qtd=1.0
A37: 17FH37A6 | B37: RPS Power Panel - Radio Power Supply - 15V | C37: Controls (MCA, train control, er etc) | D37: MCA | F37: 1 | I37: 491.25711 | J37: 615.14789 | K37: 615.14789 | L37: 2534.8867 | M37: 3174.1631 | N37: 2534.8867 | P37: PAC (Brazil BRL) | Q37: Brazilian factory PAC price (local Brazilian cost)
A38: 41A240644P2 | B38: HORN MAGNET VALVE | C38: Controls (MCA, train control, er etc) | D38: TRAIN CONTROL | F38: 1 | I38: 461.70053 | J38: 578.13741 | K38: 578.13741 | L38: 2382.3747 | M38: 2983.189 | N38: 2382.3747 | P38: PAC (Brazil BRL) | Q38: Brazilian factory PAC price (local Brazilian cost)
A39: 41A296352CMP387 | B39: ETHERNET CABLE | C39: Controls (MCA, train control, er etc) | D39: MCA | F39: 1 | I39: 413.22564 | J39: 517.43757 | K39: 517.43757 | L39: 2132.2443 | M39: 2669.9779 | N39: 2132.2443 | P39: PAC (Brazil BRL) | Q39: Brazilian factory PAC price (local Brazilian cost) | S39: Wire/Cable | T39: Already nationalized (PAC) | U39: 2660.402 | V39: 2669.9779 | W39: Import is cheaper (by R$ 9.58)
A40: 41B511393P2 | B40: Battery Knife Switch | C40: Power | D40: POWER | F40: 1 | I40: 347.82993 | J40: 435.54962 | K40: 435.54962 | L40: 1794.8024 | M40: 2247.436 | N40: 1794.8024 | P40: PAC (Brazil BRL) | Q40: Brazilian factory PAC price (local Brazilian cost)
...

Sheet GDT Integration and Assembly
A1: GDT Category | B1: Item / Service or Material Description | C1: Direct Cost BRL | D1: Direct Cost USD (@ 5.16) | E1: Gross Price BRL (Including PIS/COFINS and ICMS) | F1: Gross Price USD (Including PIS/COFINS and ICMS) | G1: Notes / Calculation Details
A2: Integration / Container Materials | B2: Container + enviromental Report | C2: 70000 | D2: 13565.891 | E2: 87653.393 | F2: 16987.092 | G2: Não incluso transporte do container
A3: Integration / Container Materials | B3: Pneumatics (tubulações, 14un mangueiras, 30un torneiras, conexões) | C3: 25000 | D3: 4844.9612 | E3: 31304.783 | F3: 6066.8185 | G3: Conexões pneumáticas gerais
A4: Integration / Container Materials | B4: Rack Electrical Connection | C4: 25000 | D4: 4844.9612 | E4: 31304.783 | F4: 6066.8185 | G4: Chicotes e passagem de cabos
A5: Integration / Container Materials | B5: Internal Electrical System (cabeamento, iluminação interna, 4un strobe, 6un steplights) | C5: 5000 | D5: 968.99225 | E5: 6260.9567 | F5: 1213.3637 | G5: Horn and headlight not needed
A6: Integration / Container Materials | B6: MU Connectors (4un), MU Jumpers (2un) | C6: 60000 | D6: 11627.907 | E6: 75131.48 | F6: 14560.364 | G6: Considerando eletrodutos e alongamento de cabeamento do container ao vagão
A7: Integration / Container Materials | B7: Air Conditioning, Inverter and Power | C7: 100000 | D7: 19379.845 | E7: 125219.13 | F7: 24267.274 | G7: Ar condicionado, inversor e potência para troca de calor
A8: Integration / Container Materials | B8: Container Thermal Insulation | C8: 100000 | D8: 19379.845 | E8: 125219.13 | F8: 24267.274 | G8: Isolamento térmico interno
A9: Integration / Container Materials | B9: Steel (railcar repair, ladder and access door) | C9: 12500 | D9: 2422.4806 | E9: 15652.392 | F9: 3033.4092 | G9: 25 reais por quilo
A10: Integration / Container Materials | B10: Painting and Lettering (Lettering) | C10: 5000 | D10: 968.99225 | E10: 6260.9567 | F10: 1213.3637 | G10: Não considerando pintar o vagão inteiro
A11: Integration / Container Materials | B11: Miscellaneous | C11: 10000 | D11: 1937.9845 | E11: 12521.913 | F11: 2426.7274 | G11: Insumos e materiais diversos
A12: Labor and Field Services | B12: Assembly and Integration Labor (Labor Cost) | C12: 122752 | D12: 23789.147 | E12: 153708.99 | F12: 29788.564 | G12: 1.096 horas (mecânica, elétrica, solda, pintura e campo) @ R$ 112/h
A13: Labor and Field Services | B13: Engineering / Project Design (NRE) | C13: 39424 | D13: 7640.3101 | E13: 49366.391 | F13: 9567.1301 | G13: 1 engenheiro + 1 projetista durante 1 mês
... A19: TOTAL GDT ROLLUP | B19: Total Integration, Adaptation and Services | C19: 707790.6 | D19: 137168.72 | E19: 886289.26 | F19: 171761.48 | G19: Sum of all additional materials and services from the rollup

Sheet Missing Items
A1: Part Number | B1: Description | C1: System | D1: Subsystem | E1: Status / Notes
A2: 41A296326CYP77 | B2: M12-A_ MALE_ 8-PIN_ STRAIGHT BSH | C2: SKID Assembly | D2: SKID (Skid) | E2: Quotation pending (no USD or BRL price)
A3: 41A296352PTP272 | B3: BC-PRECISION NAVIGATION MODULE | C3: SKID Assembly | D3: SKID (Skid) | E3: Quotation pending (no USD or BRL price)
A4: 41A296352PTP58 | B4: AY-DISPLAY CSX PTC DISPLAY | C4: SKID Assembly | D4: SKID (Skid) | E4: Quotation pending (no USD or BRL price)
A5: 41A296352PTP292 | B5: AX-POWER SUPPLY 13.6 V | C5: SKID Assembly | D5: SKID (Skid) | E5: Quotation pending (no USD or BRL price)
A6: MODEM ATT | B6: MODEM ATT | C6: SKID Assembly | D6: SKID (Skid) | E6: Quotation pending (no USD or BRL price)
A7: 84A237085AJP1 | B7: C-GoLIN EP_3 SMA_M2 CELL MODEM | C7: SKID Assembly | D7: Controls (MCA, train control, er etc) | E7: Quotation pending (no USD or BRL price)
A8: 17FL400B | B8: ST-DEVELOPER v19.4 | C8: SKID Assembly | D8: SKID (Skid) | E8: Quotation pending (no USD or BRL price)
A9: 41A296352CMP448 | B9: FB-DIGITAL RADIO MODULE | C9: SKID Assembly | D9: SKID (Skid) | E9: Quotation pending (no USD or BRL price)
A10: 41A296352PTP326 | B10: BH-WABTEC TRAIN MANAGEMENT COMPUTER _WTMC_ | C10: SKID Assembly | D10: SKID (Skid) | E10: Quotation pending (no USD or BRL price)
A11: 17FM711C3 | B11: H-PANEL DBM | C11: SKID Assembly | D11: SKID (Skid) | E11: Quotation pending (no USD or BRL price)
A12: 41A296352BCP9 | B12: N-HEAD OF TRAIN DEVICE | C12: SKID Assembly | D12: SKID (Skid) | E12: Quotation pending (no USD or BRL price)
... A22: PTC-FILT-NB-220-MIL-MF | B22: 220 Mhz PTC FILTER | C22: SKID Assembly | D22: later | E22: Quotation pending (no USD or BRL price)
B23: PTC Junction Box | C23: SKID Assembly | D23: SKID (Skid) | E23: Quotation pending (no USD or BRL price)
A24: 41A296352LUP15 | B24: 455 MHz Antenna (DPA, DPB, EOT ) | C24: SKID Assembly | D24: SKID (Skid) | E24: Quotation pending (no USD or BRL price)
A25: 84D749224G1 | B25: Power resistor | C25: SKID Assembly | D25: Battery Skid? | E25: Quotation pending (no USD or BRL price)
