Workbook

Sheet Itens do Rack
A1: ITENS IMPORTADOS DOS EUA - grupo de cada item (altere a coluna D para mover um item de grupo)
A3: Part Number | B3: Descrição | C3: Subsistema | D3: Grupo | E3: Qtd | F3: Custo Unit. USD | G3: Raw Cost BRL | H3: TP % | I3: TP BRL | J3: Frete Intl BRL | K3: II % (normal) | L3: II BRL (sem ex-tarifário) | M3: Ex-tarifário se aplica? (cenário Rack) | N3: Ex-tarifário se aplica? (cenário Rack + Fastbrake) | O3: Peso (kg, total)
A4: 84A215295P62 | B4: Pneumatic Brake Control System (Including lament and control portions) Includes EM EAB Control Functionality | C4: Fastbrake | D4: Fastbrake | E4: 1 | F4: 23409.1 | G4: =F4*E4*'Cenário P&L'!$B$3 | H4: 0.13 | I4: =G4*H4 | J4: =(G4+I4)*0.012295642058762843 | K4: 0.18 | L4: =(G4+I4+J4)*K4 | M4: =IF(D4="Rack",1,0) | N4: =IF(OR(D4="Rack",D4="Fastbrake"),1,0) | O4: 134.263
A5: 84A215295P73 | B5: Air Brake Handle Assembly (AAR Console) | C5: Fastbrake | D5: Fastbrake | E5: 1 | F5: 5702.83 | G5: =F5*E5*'Cenário P&L'!$B$3 | H5: 0.13 | I5: =G5*H5 | J5: =(G5+I5)*0.012295642058762843 | K5: 0.18 | L5: =(G5+I5+J5)*K5 | M5: =IF(D5="Rack",1,0) | N5: =IF(OR(D5="Rack",D5="Fastbrake"),1,0) | O5: 7.938
A6: 84A215295P3 | B6: POU-to-Handle cable 18' length | C6: Fastbrake | D6: Fastbrake | E6: 1 | F6: 1036.89 | G6: =F6*E6*'Cenário P&L'!$B$3 | H6: 0.13 | I6: =G6*H6 | J6: =(G6+I6)*0.012295642058762843 | K6: 0.18 | L6: =(G6+I6+J6)*K6 | M6: =IF(D6="Rack",1,0) | N6: =IF(OR(D6="Rack",D6="Fastbrake"),1,0) | O6: 1.247
A7: 84A222059P5 | B7: BATTERIES | C7: POWER | D7: Other | E7: 2 | F7: 15685.42 | G7: =F7*E7*'Cenário P&L'!$B$3 | H7: 0.172 | I7: =G7*H7 | J7: =(G7+I7)*0.012295642058762843 | K7: 0.18 | L7: =(G7+I7+J7)*K7 | M7: =IF(D7="Rack",1,0) | N7: =IF(OR(D7="Rack",D7="Fastbrake"),1,0) | O7: 2246.19
A8: 41A296352LUG24 | B8: CSX Antenna Enclosure Arrangement | C8: ANTENNA KIT Master | D8: Other | E8: 1 | F8: 30000 | G8: =F8*E8*'Cenário P&L'!$B$3 | H8: 0.172 | I8: =G8*H8 | J8: =(G8+I8)*0.012295642058762843 | K8: 0.18 | L8: =(G8+I8+J8)*K8 | M8: =IF(D8="Rack",1,0) | N8: =IF(OR(D8="Rack",D8="Fastbrake"),1,0) | O8: 136.078
A9: 17KC108E28 | B9: MASTER CONTROLLER | C9: TRAIN CONTROL | D9: Other | E9: 1 | F9: 5877.102 | G9: =F9*E9*'Cenário P&L'!$B$3 | H9: 0.13 | I9: =G9*H9 | J9: =(G9+I9)*0.012295642058762843 | K9: 0.18 | L9: =(G9+I9+J9)*K9 | M9: =IF(D9="Rack",1,0) | N9: =IF(OR(D9="Rack",D9="Fastbrake"),1,0) | O9: 25.855
A10: 41A296352DNP55 | B10: VOICE RADIO RITRON | C10: VOICE RADIO | D10: Other | E10: 1 | F10: 3933 | G10: =F10*E10*'Cenário P&L'!$B$3 | H10: 0.172 | I10: =G10*H10 | J10: =(G10+I10)*0.012295642058762843 | K10: 0.18 | L10: =(G10+I10+J10)*K10 | M10: =IF(D10="Rack",1,0) | N10: =IF(OR(D10="Rack",D10="Fastbrake"),1,0) | O10: 7.575
A11: 41B546155P2 | B11: Horn | C11: TRAIN CONTROL | D11: Other | E11: 1 | F11: 1891.99 | G11: =F11*E11*'Cenário P&L'!$B$3 | H11: 0.172 | I11: =G11*H11 | J11: =(G11+I11)*0.012295642058762843 | K11: 0.18 | L11: =(G11+I11+J11)*K11 | M11: =IF(D11="Rack",1,0) | N11: =IF(OR(D11="Rack",D11="Fastbrake"),1,0) | O11: 4.536
A12: (no PN) | B12: Ditchlight Control Box (SMART BOX-V3-DLC ) | C12: TRAIN CONTROL | D12: Other | E12: 2 | F12: 800 | G12: =F12*E12*'Cenário P&L'!$B$3 | H12: 0.13 | I12: =G12*H12 | J12: =(G12+I12)*0.012295642058762843 | K12: 0.18 | L12: =(G12+I12+J12)*K12 | M12: =IF(D12="Rack",1,0) | N12: =IF(OR(D12="Rack",D12="Fastbrake"),1,0) | O12: 4.536
A13: 41D758679BJG16 84D704379AFG1 | B13: EC Part NumberL ASM | C13: Circuit Breaker | D13: Other | E13: 1 | F13: 1572.36 | G13: =F13*E13*'Cenário P&L'!$B$3 | H13: 0.13 | I13: =G13*H13 | J13: =(G13+I13)*0.012295642058762843 | K13: 0.126 | L13: =(G13+I13+J13)*K13 | M13: =IF(D13="Rack",1,0) | N13: =IF(OR(D13="Rack",D13="Fastbrake"),1,0) | O13: 4.99
A14: (no PN) | B14: LED Ditch Light | C14: TRAIN CONTROL | D14: Other | E14: 4 | F14: 375 | G14: =F14*E14*'Cenário P&L'!$B$3 | H14: 0.13 | I14: =G14*H14 | J14: =(G14+I14)*0.012295642058762843 | K14: 0.18 | L14: =(G14+I14+J14)*K14 | M14: =IF(D14="Rack",1,0) | N14: =IF(OR(D14="Rack",D14="Fastbrake"),1,0) | O14: 3.628
A15: RCCR-RMTCBL-RA-CUSTOM | B15: VOICE RADIO RITRON CABLE,REMOTE,RR-225/XXX, RCCR,RIGHT ANGLE,19-PIN,FLAME RETARDANT | C15: VOICE RADIO | D15: Other | E15: 1 | F15: 761 | G15: =F15*E15*'Cenário P&L'!$B$3 | H15: 0.172 | I15: =G15*H15 | J15: =(G15+I15)*0.012295642058762843 | K15: 0.18 | L15: =(G15+I15+J15)*K15 | M15: =IF(D15="Rack",1,0) | N15: =IF(OR(D15="Rack",D15="Fastbrake"),1,0)
A16: 84A201850P4 | B16: ENGINE CONTROL SWITCH | C16: TRAIN CONTROL | D16: Other | E16: 1 | F16: 171.544 | G16: =F16*E16*'Cenário P&L'!$B$3 | H16: 0.13 | I16: =G16*H16 | J16: =(G16+I16)*0.012295642058762843 | K16: 0.18 | L16: =(G16+I16+J16)*K16 | M16: =IF(D16="Rack",1,0) | N16: =IF(OR(D16="Rack",D16="Fastbrake"),1,0)
A17: RCCR-PWRCBL | B17: CABLE, PWR, 72V,RA,6.5FT (78").,RR-070,RCCR | C17: VOICE RADIO | D17: Other | E17: 1 | F17: 159 | G17: =F17*E17*'Cenário P&L'!$B$3 | H17: 0.13 | I17: =G17*H17 | J17: =(G17+I17)*0.012295642058762843 | K17: 0.18 | L17: =(G17+I17+J17)*K17 | M17: =IF(D17="Rack",1,0) | N17: =IF(OR(D17="Rack",D17="Fastbrake"),1,0)
A18: 41A212414P31, 41A212414P3 2-Pole Option | B18: AUTOCOUPLER CIRCUIT BREAKER, CCB(2A) | C18: Circuit Breaker | D18: Other | E18: 1 | F18: 22.0206 | G18: =F18*E18*'Cenário P&L'!$B$3 | H18: 0.13 | I18: =G18*H18 | J18: =(G18+I18)*0.012295642058762843 | K18: 0.08 | L18: =(G18+I18+J18)*K18 | M18: =IF(D18="Rack",1,0) | N18: =IF(OR(D18="Rack",D18="Fastbrake"),1,0) | O18: 0.093
A19: 41A296352CMP437 | B19: Dual Processor Module (DPM)+ LXA (Distributed Power Radio) | C19: LXA | D19: Rack | E19: 1 | F19: 63100.819 | G19: =F19*E19*'Cenário P&L'!$B$3 | H19: 0.13 | I19: =G19*H19 | J19: =(G19+I19)*0.012295642058762843 | K19: 0.18 | L19: =(G19+I19+J19)*K19 | M19: =IF(D19="Rack",1,0) | N19: =IF(OR(D19="Rack",D19="Fastbrake"),1,0) | O19: 4.536
A20: 37495P | B20: KIT ETMS VIRGIN TRAINS FEC EVO44 | C20: PTC KIT MASTER | D20: Rack | E20: 1 | F20: 28529 | G20: =F20*E20*'Cenário P&L'!$B$3 | H20: 0.13 | I20: =G20*H20 | J20: =(G20+I20)*0.012295642058762843 | K20: 0.18 | L20: =(G20+I20+J20)*K20 | M20: =IF(D20="Rack",1,0) | N20: =IF(OR(D20="Rack",D20="Fastbrake"),1,0) | O20: 45.359
A21: 41A296352DNP37 | B21: RADIO PRAD PTC RADIO | C21: PTC | D21: Rack | E21: 1 | F21: 20000 | G21: =F21*E21*'Cenário P&L'!$B$3 | H21: 0.172 | I21: =G21*H21 | J21: =(G21+I21)*0.012295642058762843 | K21: 0.18 | L21: =(G21+I21+J21)*K21 | M21: =IF(D21="Rack",1,0) | N21: =IF(OR(D21="Rack",D21="Fastbrake"),1,0) | O21: 9.616
A22: 17FM878A6 | B22: NIO 2.0 | C22: MCA | D22: Rack | E22: 3 | F22: 5176.9118 | G22: =F22*E22*'Cenário P&L'!$B$3 | H22: 0.172 | I22: =G22*H22 | J22: =(G22+I22)*0.012295642058762843 | K22: 0.18 | L22: =(G22+I22+J22)*K22 | M22: =IF(D22="Rack",1,0) | N22: =IF(OR(D22="Rack",D22="Fastbrake"),1,0) | O22: 25.854
A23: L7000083-900 | B23: Wireless Communications Management Module, Gen 3 (WCM3)​ | C23: TRAIN CONTROL | D23: Rack | E23: 2 | F23: 5000 | G23: =F23*E23*'Cenário P&L'!$B$3 | H23: 0.13 | I23: =G23*H23 | J23: =(G23+I23)*0.012295642058762843 | K23: 0.18 | L23: =(G23+I23+J23)*K23 | M23: =IF(D23="Rack",1,0) | N23: =IF(OR(D23="Rack",D23="Fastbrake"),1,0) | O23: 4.536
A24: 84A237085AEP121 | B24: 8 Slot ACC Chassis for MCA w/ i7 HPEAP and SMM2 Cards | C24: TRAIN CONTROL | D24: Rack | E24: 1 | F24: 8000 | G24: =F24*E24*'Cenário P&L'!$B$3 | H24: 0.13 | I24: =G24*H24 | J24: =(G24+I24)*0.012295642058762843 | K24: 0.18 | L24: =(G24+I24+J24)*K24 | M24: =IF(D24="Rack",1,0) | N24: =IF(OR(D24="Rack",D24="Fastbrake"),1,0) | O24: 9.072
A25: 17FM868B2 | B25: SNIO | C25: MCA | D25: Rack | E25: 1 | F25: 4150.9559 | G25: =F25*E25*'Cenário P&L'!$B$3 | H25: 0.172 | I25: =G25*H25 | J25: =(G25+I25)*0.012295642058762843 | K25: 0.18 | L25: =(G25+I25+J25)*K25 | M25: =IF(D25="Rack",1,0) | N25: =IF(OR(D25="Rack",D25="Fastbrake"),1,0) | O25: 4.99
A26: 32613P | B26: KIT ETMS AXLE INTERFACE FOR WPart Number 29266P | C26: PTC | D26: Rack | E26: 1 | F26: 2981.71 | G26: =F26*E26*'Cenário P&L'!$B$3 | H26: 0.13 | I26: =G26*H26 | J26: =(G26+I26)*0.012295642058762843 | K26: 0.18 | L26: =(G26+I26+J26)*K26 | M26: =IF(D26="Rack",1,0) | N26: =IF(OR(D26="Rack",D26="Fastbrake"),1,0) | O26: 4.536
A27: 41A296352PTP306/41A296352PTP122 | B27: Assembled Air Manifold (Contains 3 pressure sensors mounted in appropriate locations on Air Manifold.) | C27: PTC | D27: Rack | E27: 1 | F27: 595.7889 | G27: =F27*E27*'Cenário P&L'!$B$3 | H27: 0.13 | I27: =G27*H27 | J27: =(G27+I27)*0.012295642058762843 | K27: 0.16 | L27: =(G27+I27+J27)*K27 | M27: =IF(D27="Rack",1,0) | N27: =IF(OR(D27="Rack",D27="Fastbrake"),1,0) | O27: 5.897
A28: 32447P | B28: ASY CABLE WHEEL TACH AC EVO/SD70 ACE | C28: PTC | D28: Rack | E28: 1 | F28: 411.22 | G28: =F28*E28*'Cenário P&L'!$B$3 | H28: 0.13 | I28: =G28*H28 | J28: =(G28+I28)*0.012295642058762843 | K28: 0.18 | L28: =(G28+I28+J28)*K28 | M28: =IF(D28="Rack",1,0) | N28: =IF(OR(D28="Rack",D28="Fastbrake"),1,0)
A29: 41A296352PTP10/319/34 | B29: VALVE Part NumberEUMATIC NC/CO (Penalty Magnet Valve) Graham-White 812-142 | C29: PTC | D29: Rack | E29: 1 | F29: 404.6239 | G29: =F29*E29*'Cenário P&L'!$B$3 | H29: 0.13 | I29: =G29*H29 | J29: =(G29+I29)*0.012295642058762843 | K29: 0.18 | L29: =(G29+I29+J29)*K29 | M29: =IF(D29="Rack",1,0) | N29: =IF(OR(D29="Rack",D29="Fastbrake"),1,0)
A30: 84A231123CSP30 | B30: Axle Tac - WRE Part Number: 29266P | C30: PTC | D30: Rack | E30: 1 | F30: 205 | G30: =F30*E30*'Cenário P&L'!$B$3 | H30: 0.13 | I30: =G30*H30 | J30: =(G30+I30)*0.012295642058762843 | K30: 0.18 | L30: =(G30+I30+J30)*K30 | M30: =IF(D30="Rack",1,0) | N30: =IF(OR(D30="Rack",D30="Fastbrake"),1,0)
A31: 84A207079ABP1 | B31: 41A313392DCP18 alternative 300" / | C31: Wiring | D31: Rack | E31: 25 | F31: 8.118 | G31: =F31*E31*'Cenário P&L'!$B$3 | H31: 0.13 | I31: =G31*H31 | J31: =(G31+I31)*0.012295642058762843 | K31: 0.144 | L31: =(G31+I31+J31)*K31 | M31: =IF(D31="Rack",1,0) | N31: =IF(OR(D31="Rack",D31="Fastbrake"),1,0) | O31: 5.675
A32: 41A216641AMP126 | B32: NIO1D CONNECTOR BACKSHELL | C32: Wiring | D32: Rack | E32: 3 | F32: 29.9096 | G32: =F32*E32*'Cenário P&L'!$B$3 | H32: 0.13 | I32: =G32*H32 | J32: =(G32+I32)*0.012295642058762843 | K32: 0.18 | L32: =(G32+I32+J32)*K32 | M32: =IF(D32="Rack",1,0) | N32: =IF(OR(D32="Rack",D32="Fastbrake"),1,0) | O32: 0
A33: 17 pin MS3106-20-29F | B33: Head of Train Device - Padom - J2 Connector | C33: Wiring | D33: Rack | E33: 1 | F33: 79.83 | G33: =F33*E33*'Cenário P&L'!$B$3 | H33: 0.13 | I33: =G33*H33 | J33: =(G33+I33)*0.012295642058762843 | K33: 0.18 | L33: =(G33+I33+J33)*K33 | M33: =IF(D33="Rack",1,0) | N33: =IF(OR(D33="Rack",D33="Fastbrake"),1,0)
A34: 41A216641AMP125 | B34: NIO1A CONNECTOR BACKSHELL | C34: Wiring | D34: Rack | E34: 3 | F34: 24.1998 | G34: =F34*E34*'Cenário P&L'!$B$3 | H34: 0.13 | I34: =G34*H34 | J34: =(G34+I34)*0.012295642058762843 | K34: 0.18 | L34: =(G34+I34+J34)*K34 | M34: =IF(D34="Rack",1,0) | N34: =IF(OR(D34="Rack",D34="Fastbrake"),1,0) | O34: 0.015
A35: 5088-7000-P4611-0000000-ND‎ | B35: POE Power Connector on SMM2 (M12 FEMALE 0 L-CODED FIELD-WIREA) | C35: TRAIN CONTROL | D35: Rack | E35: 1 | F35: 72.41 | G35: =F35*E35*'Cenário P&L'!$B$3 | H35: 0.13 | I35: =G35*H35 | J35: =(G35+I35)*0.012295642058762843 | K35: 0.18 | L35: =(G35+I35+J35)*K35 | M35: =IF(D35="Rack",1,0) | N35: =IF(OR(D35="Rack",D35="Fastbrake"),1,0)
A36: 41A296352PTP67 | B36: CABLE CSX 12V P WR CBL | C36: MCA | D36: Rack | E36: 1 | F36: 71.94 | G36: =F36*E36*'Cenário P&L'!$B$3 | H36: 0.13 | I36: =G36*H36 | J36: =(G36+I36)*0.012295642058762843 | K36: 0.18 | L36: =(G36+I36+J36)*K36 | M36: =IF(D36="Rack",1,0) | N36: =IF(OR(D36="Rack",D36="Fastbrake"),1,0)
A37: 41A296352PTP69 | B37: CABLE CSX 74V P WR CBL | C37: MCA | D37: Rack | E37: 1 | F37: 71.94 | G37: =F37*E37*'Cenário P&L'!$B$3 | H37: 0.13 | I37: =G37*H37 | J37: =(G37+I37)*0.012295642058762843 | K37: 0.18 | L37: =(G37+I37+J37)*K37 | M37: =IF(D37="Rack",1,0) | N37: =IF(OR(D37="Rack",D37="Fastbrake"),1,0)
A38: 41A216641AMP93 | B38: NIO1E CONNECTOR | C38: Wiring | D38: Rack | E38: 3 | F38: 23.9499 | G38: =F38*E38*'Cenário P&L'!$B$3 | H38: 0.13 | I38: =G38*H38 | J38: =(G38+I38)*0.012295642058762843 | K38: 0.18 | L38: =(G38+I38+J38)*K38 | M38: =IF(D38="Rack",1,0) | N38: =IF(OR(D38="Rack",D38="Fastbrake"),1,0) | O38: 0.162
A39: 41A216641AMP103 | B39: NIO1D CONNECTOR | C39: Wiring | D39: Rack | E39: 3 | F39: 21.2198 | G39: =F39*E39*'Cenário P&L'!$B$3 | H39: 0.13 | I39: =G39*H39 | J39: =(G39+I39)*0.012295642058762843 | K39: 0.18 | L39: =(G39+I39+J39)*K39 | M39: =IF(D39="Rack",1,0) | N39: =IF(OR(D39="Rack",D39="Fastbrake"),1,0) | O39: 0.135
A40: 16246P | B40: Flexi-Axle - WRE Part Number: 16246P | C40: PTC | D40: Rack | E40: 1 | F40: 59.75 | G40: =F40*E40*'Cenário P&L'!$B$3 | H40: 0.13 | I40: =G40*H40 | J40: =(G40+I40)*0.012295642058762843 | K40: 0.18 | L40: =(G40+I40+J40)*K40 | M40: =IF(D40="Rack",1,0) | N40: =IF(OR(D40="Rack",D40="Fastbrake"),1,0)
A41: 41A216641AMP99 | B41: NIO1B CONNECTOR | C41: Wiring | D41: Rack | E41: 3 | F41: 19.67 | G41: =F41*E41*'Cenário P&L'!$B$3 | H41: 0.13 | I41: =G41*H41 | J41: =(G41+I41)*0.012295642058762843 | K41: 0.18 | L41: =(G41+I41+J41)*K41 | M41: =IF(D41="Rack",1,0) | N41: =IF(OR(D41="Rack",D41="Fastbrake"),1,0) | O41: 0
...

Sheet Cenário P&L
A1: PATHFINDER - CENÁRIO EX-TARIFÁRIO DO RACK
A2: PARÂMETROS
A3: Câmbio (USD->BRL) | B3: 5.1
A4: Total Deal Margin (TDM) | B4: 0.45
A5: II % com ex-tarifário | B5: 0
A6: PIS/COFINS (blended) | B6: 0.1006
A7: ICMS | B7: 0.18
A8: IPI (blended) | B8: 0.0969
A9: Frete nacional (cotação real, fixo) | B9: 21753.105
A10: Itens PAC (custo local all-in) | B10: 166060.16
A11: Supermetal - integração/montagem GDT (custo direto) | B11: 707790.6
A12: Custo de montagem / integração do Rack (input, se houver) | B12: 0
A13: Frete extra do Rack montado (input, se houver) | B13: 0
A14: COMPARAÇÃO DE CENÁRIOS
B15: Base (atual) - BRL | C15: Base (atual) - USD | D15: Ex-tarifário: Rack (LXA+MCA+GoLinc+PTC+conectores) - BRL | E15: Ex-tarifário: Rack (LXA+MCA+GoLinc+PTC+conectores) - USD | F15: Ex-tarifário: Rack + Fastbrake - BRL | G15: Ex-tarifário: Rack + Fastbrake - USD
A16: Raw cost - itens importados | B16: =SUM('Itens do Rack'!G4:G50) | C16: =B16/$B$3 | D16: =SUM('Itens do Rack'!G4:G50) | E16: =D16/$B$3 | F16: =SUM('Itens do Rack'!G4:G50) | G16: =F16/$B$3
A17: Itens PAC | B17: =$B$10 | C17: =B17/$B$3 | D17: =$B$10 | E17: =D17/$B$3 | F17: =$B$10 | G17: =F17/$B$3
A18: TP - Transfer Price | B18: =SUM('Itens do Rack'!I4:I50) | C18: =B18/$B$3 | D18: =SUM('Itens do Rack'!I4:I50) | E18: =D18/$B$3 | F18: =SUM('Itens do Rack'!I4:I50) | G18: =F18/$B$3
A19: Frete internacional | B19: =SUM('Itens do Rack'!J4:J50) | C19: =B19/$B$3 | D19: =SUM('Itens do Rack'!J4:J50) | E19: =D19/$B$3 | F19: =SUM('Itens do Rack'!J4:J50) | G19: =F19/$B$3
A20: II - Imposto de importação | B20: =SUM('Itens do Rack'!L4:L50) | C20: =B20/$B$3 | D20: =SUM('Itens do Rack'!L4:L50)-SUMPRODUCT('Itens do Rack'!L4:L50,'Itens do Rack'!M4:M50)+SUMPRODUCT(('Itens do Rack'!G4:G50+'Itens do Rack'!I4:I50+'Itens do Rack'!J4:J50),'Itens do Rack'!M4:M50)*$B$5 | E20: =D20/$B$3 | F20: =SUM('Itens do Rack'!L4:L50)-SUMPRODUCT('Itens do Rack'!L4:L50,'Itens do Rack'!N4:N50)+SUMPRODUCT(('Itens do Rack'!G4:G50+'Itens do Rack'!I4:I50+'Itens do Rack'!J4:J50),'Itens do Rack'!N4:N50)*$B$5 | G20: =F20/$B$3
A21: Frete nacional | B21: =$B$9 | C21: =B21/$B$3 | D21: =$B$9 | E21: =D21/$B$3 | F21: =$B$9 | G21: =F21/$B$3
A22: Supermetal - integração/montagem GDT | B22: =$B$11 | C22: =B22/$B$3 | D22: =$B$11 | E22: =D22/$B$3 | F22: =$B$11 | G22: =F22/$B$3
A23: Montagem / integração do Rack | B23: =$B$12 | C23: =B23/$B$3 | D23: =$B$12 | E23: =D23/$B$3 | F23: =$B$12 | G23: =F23/$B$3
A24: Frete extra (Rack montado) | B24: =$B$13 | C24: =B24/$B$3 | D24: =$B$13 | E24: =D24/$B$3 | F24: =$B$13 | G24: =F24/$B$3
A25: CUSTO FINAL (com TP): | B25: =SUM(B16:B24) | C25: =B25/$B$3 | D25: =SUM(D16:D24) | E25: =D25/$B$3 | F25: =SUM(F16:F24) | G25: =F25/$B$3
A26: Base p/ margem (Custo Final - TP) | B26: =B25-B18 | C26: =B26/$B$3 | D26: =D25-D18 | E26: =D26/$B$3 | F26: =F25-F18 | G26: =F26/$B$3
A27: Preço líquido s/ TP (Base / (1 - TDM)) | B27: =B26/(1-$B$4) | C27: =B27/$B$3 | D27: =D26/(1-$B$4) | E27: =D27/$B$3 | F27: =F26/(1-$B$4) | G27: =F27/$B$3
A28: PREÇO LÍQUIDO ('NOSSO PREÇO'): | B28: =B27+B18 | C28: =B28/$B$3 | D28: =D27+D18 | E28: =D28/$B$3 | F28: =F27+F18 | G28: =F28/$B$3
A29: + PIS/COFINS (por dentro) | B29: =B28/(1-$B$6) | C29: =B29/$B$3 | D29: =D28/(1-$B$6) | E29: =D29/$B$3 | F29: =F28/(1-$B$6) | G29: =F29/$B$3
A30: + ICMS (por dentro) | B30: =B29/(1-$B$7) | C30: =B30/$B$3 | D30: =D29/(1-$B$7) | E30: =D30/$B$3 | F30: =F29/(1-$B$7) | G30: =F30/$B$3
A31: + IPI (por fora) | B31: =B30*$B$8 | C31: =B31/$B$3 | D31: =D30*$B$8 | E31: =D31/$B$3 | F31: =F30*$B$8 | G31: =F31/$B$3
A32: PREÇO FINAL AO CLIENTE: | B32: =B30+B31 | C32: =B32/$B$3 | D32: =D30+D31 | E32: =D32/$B$3 | F32: =F30+F31 | G32: =F32/$B$3
A34: Economia no Preço Líquido vs Base | D34: =B28-D28 | E34: =D34/$B$3 | F34: =B28-F28 | G34: =F34/$B$3
A35: Economia no Preço Final vs Base | D35: =B32-D32 | E35: =D35/$B$3 | F35: =B32-F32 | G35: =F35/$B$3
A37: Peso total do grupo Rack (kg) | B37: =SUMIF('Itens do Rack'!D4:D50,"Rack",'Itens do Rack'!O4:O50)
A39: - Ex-tarifário só zera a linha do II. As alíquotas de IPI/PIS/COFINS/ICMS não mudam (neste modelo são impostos de saída sobre o preço de venda, então só caem porque a base de preço cai).
A40: - O ex-tarifário é concedido por NCM + descrição técnica via MDIC/GECEX (consulta pública, 1-2 anos, sem retroatividade). Sistemas integrados podem ser recusados - o PN único do Rack precisa ser classificado numa NCM coberta por um ex.
A41: - Fastbrake / NYAB CCBII: não sabemos se existe ex - mostrado como cenário separado.
A42: - Envio do Rack montado: frete mantido no % de valor da China Gate; cotação de carga montada (peso/volume) e mão de obra de montagem do Rack são inputs acima, padrão 0.
A43: - TP inalterado (13%/17,2% por grupo); com um PN único do Rack, o TP seria aplicado sobre o preço do kit - confirmar com o responsável por transfer pricing.
