Workbook

Sheet Item List
A1: ITEM LIST - MRS Pathfinder GDT Cost Proposal
A3: Part Number | B3: Description | C3: System | D3: SubSystem | E3: Quantity | F3: Cost Source | G3: Unit Cost USD (Imported items, no markup) | H3: Unit Cost BRL (PAC items, local nationalized cost) | I3: Weight (kg) | J3: Weight Confidence | K3: NCM | L3: Dimensions (L x H x W, in) | M3: Notes
A4: 41A296352CMP437 | B4: Dual Processor Module (DPM)+ LXA (Distributed Power Radio) | C4: Controls (MCA, train control, er etc) | D4: LXA | E4: 1 | F4: Imported (USA) | G4: 63100.819 | I4: 4.536 | J4: High | K4: 90328990
A5: 37495P | B5: KIT ETMS VIRGIN TRAINS FEC EVO44 | C5: PTC | D5: PTC KIT MASTER | E5: 1 | F5: Imported (USA) | G5: 28529 | I5: 45.359 | J5: High
A6: 84A222059P5 | B6: BATTERIES | C6: Power | D6: POWER | E6: 2 | F6: Imported (USA) | G6: 15685.42 | I6: 1123.095 | J6: High
A7: 41A296352LUG24 | B7: CSX Antenna Enclosure Arrangement | C7: Connectivity | D7: ANTENNA KIT Master | E7: 1 | F7: Imported (USA) | G7: 30000 | I7: 136.078 | J7: High
A8: 84A215295P62 | B8: Pneumatic Brake Control System (Including lament and control portions) Includes EM EAB Control Functionality | C8: Air | D8: Fastbrake | E8: 1 | F8: Imported (USA) | G8: 23409.1 | I8: 134.263 | J8: High
A9: 41A296352DNP37 | B9: RADIO PRAD PTC RADIO | C9: PTC | D9: PTC | E9: 1 | F9: Imported (USA) | G9: 20000 | I9: 9.616 | J9: High
A10: 17FM878A6 | B10: NIO 2.0 | C10: Controls (MCA, train control, er etc) | D10: MCA | E10: 3 | F10: Imported (USA) | G10: 5176.9118 | I10: 8.618 | J10: High
A11: L7000083-900 | B11: Wireless Communications Management Module, Gen 3 (WCM3)​ | C11: Controls (MCA, train control, er etc) | D11: TRAIN CONTROL | E11: 2 | F11: Imported (USA) | G11: 5000 | I11: 2.268 | J11: High
A12: 84A237085AEP121 | B12: 8 Slot ACC Chassis for MCA w/ i7 HPEAP and SMM2 Cards | C12: Controls (MCA, train control, er etc) | D12: TRAIN CONTROL | E12: 1 | F12: Imported (USA) | G12: 8000 | I12: 9.072 | J12: High
A13: 17FL472A2 | B13: TMC PANEL | C13: SKID Assembly | D13: SKID (Skid) | E13: 1 | F13: PAC (Brazil, nationalized) | H13: 58447.152 | I13: 20.412 | J13: High | K13: 85371090
A14: 17KC108E28 | B14: MASTER CONTROLLER | C14: Controls (MCA, train control, er etc) | D14: TRAIN CONTROL | E14: 1 | F14: GET (made in-house) | G14: 5877.102 | I14: 25.855 | J14: High
A15: 84A215295P73 | B15: Air Brake Handle Assembly (AAR Console) | C15: Air | D15: Fastbrake | E15: 1 | F15: Imported (USA) | G15: 5702.83 | I15: 7.938 | J15: High
A16: 17FM868B2 | B16: SNIO | C16: Controls (MCA, train control, er etc) | D16: MCA | E16: 1 | F16: Imported (USA) | G16: 4150.9559 | I16: 4.99 | J16: High
A17: 41A296352DNP55 | B17: VOICE RADIO RITRON | C17: Connectivity | D17: VOICE RADIO | E17: 1 | F17: Imported (USA) | G17: 3933 | I17: 7.575 | J17: High
A18: 32613P | B18: KIT ETMS AXLE INTERFACE FOR WPart Number 29266P | C18: PTC | D18: PTC | E18: 1 | F18: Imported (USA) | G18: 2981.71 | I18: 4.536 | J18: High
A19: 17FH40X1 | B19: LPS 17FH40 (COMMON LOGIC POWER SUPPLY) (5v, 15v, 19v, 24v) | C19: POWER | D19: POWER SUPPLY | E19: 1 | F19: PAC (Brazil, nationalized) | H19: 15041.54 | I19: 18.144 | J19: High | K19: 85044029 | L19: 24x10x20
A20: 41D758679BJG16 84D704379AFG1 | B20: EC Part NumberL ASM | C20: Power | D20: Circuit Breaker | E20: 1 | F20: GET (made in-house) | G20: 1572.36 | I20: 4.99 | J20: High | K20: 86079100 | L20: 20x3.5x25.5
A21: 41B546155P2 | B21: Horn | C21: Controls (MCA, train control, er etc) | D21: TRAIN CONTROL | E21: 1 | F21: Imported (USA) | G21: 1891.99 | I21: 4.536 | J21: High
B22: Ditchlight Control Box (SMART BOX-V3-DLC ) | C22: Controls (MCA, train control, er etc) | D22: TRAIN CONTROL | E22: 2 | F22: Imported (USA) | G22: 800 | I22: 2.268 | J22: High
B23: LED Ditch Light | C23: Controls (MCA, train control, er etc) | D23: TRAIN CONTROL | E23: 4 | F23: Imported (USA) | G23: 375 | I23: 0.907 | J23: High
A24: 17FM839B1 | B24: PANEL ASM CFD - Thin Client Display | C24: Controls (MCA, train control, er etc) | D24: MCA | E24: 1 | F24: PAC (Brazil, nationalized) | H24: 11603.717 | I24: 9.299 | J24: High | K24: 85312000 | L24: 18.5x8.5x15
A25: 17FM839A3 | B25: TCD (Thin Client Display) | C25: SKID Assembly | D25: SKID (Skid) | E25: 1 | F25: PAC (Brazil, nationalized) | H25: 11603.717 | I25: 9.299 | J25: High | K25: 85312000 | L25: 18.5x8.5x15
A26: 84A201003DAP1 | B26: ELECTRIC Bell | C26: Controls (MCA, train control, er etc) | D26: TRAIN CONTROL | E26: 1 | F26: PAC (Brazil, nationalized) | H26: 9491.4571 | I26: 8.119 | J26: High | K26: 85318000 | L26: 14.25x14.25x10
A27: 17FB193E2F | B27: GET Card | C27: GET | D27: GET Card | E27: 1 | F27: PAC (Brazil, nationalized) | H27: 9251.1239 | I27: 1.114 | J27: High | K27: 85049040 | L27: 17.2x1.95x11.2
A28: 84A215295P3 | B28: POU-to-Handle cable 18' length | C28: Air | D28: Fastbrake | E28: 1 | F28: Imported (USA) | G28: 1036.89 | I28: 1.247 | J28: Medium
A29: 41B566322ACG1 | B29: TRAINLINE RESISTOR PANEL | C29: SKID Assembly | D29: Controls (MCA, train control, er etc) | E29: 1 | F29: GET (made in-house) | I29: 2.859 | J29: High | K29: 85333990 | L29: 14x6x8.5
A30: 41A296304DDP4 | B30: G-RECTIFIER POWER BLOCK | C30: SKID Assembly | D30: Controls (MCA, train control, er etc) | E30: 20 | F30: PAC (Brazil, nationalized) | H30: 326.22301 | I30: 0.054 | J30: Low | K30: 85411099 | L30: 10.85x1.1x8.5 | M30: Weight looks wrong, verify
A31: RCCR-RMTCBL-RA-CUSTOM | B31: VOICE RADIO RITRON CABLE,REMOTE,RR-225/XXX, RCCR,RIGHT ANGLE,19-PIN,FLAME RETARDANT | C31: Connectivity | D31: VOICE RADIO | E31: 1 | F31: Imported (USA) | G31: 761
A32: 41C663693G1 | B32: PANEL CPF | C32: Power | D32: POWER | E32: 1 | F32: GET (made in-house) | I32: 5.761 | J32: High | K32: 85371090 | L32: 20.5x10.5x11.5
A33: 41A296352PTP306/41A296352PTP122 | B33: Assembled Air Manifold (Contains 3 pressure sensors mounted in appropriate locations on Air Manifold.) | C33: PTC | D33: PTC | E33: 1 | F33: Imported (USA) | G33: 595.7889 | I33: 5.897 | J33: Medium | K33: 85381000
A34: 84A232147P1 | B34: KNOB HLD DWN with washer and screw | C34: Controls (MCA, train control, er etc) | D34: TRAIN CONTROL | E34: 30 | F34: PAC (Brazil, nationalized) | H34: 127.47577 | I34: 0.045 | J34: High | K34: 83024900 | L34: 3.5x0.75x0.75
A35: 32447P | B35: ASY CABLE WHEEL TACH AC EVO/SD70 ACE | C35: PTC | D35: PTC | E35: 1 | F35: Imported (USA) | G35: 411.22
A36: 41A296352PTP10/319/34 | B36: VALVE Part NumberEUMATIC NC/CO (Penalty Magnet Valve) Graham-White 812-142 | C36: PTC | D36: PTC | E36: 1 | F36: Imported (USA) | G36: 404.6239
A37: 84A201176P1 | B37: Pathfinder Control Unit Connector (MU Plug) | C37: Controls (MCA, train control, er etc) | D37: TRAIN CONTROL | E37: 2 | F37: PAC (Brazil, nationalized) | H37: 1480.8637 | I37: 2.404 | J37: High | K37: 85366990 | L37: 7x4x7
A38: 84A201150ACP2 | B38: CROSSING BELL PUSH BUTTON SWITCH | C38: Controls (MCA, train control, er etc) | D38: TRAIN CONTROL | E38: 1 | F38: PAC (Brazil, nationalized) | H38: 2843.3769 | I38: 0.411 | J38: High | K38: 85365090 | L38: 11.8x6.4x8.05
A39: 17FH37A6 | B39: RPS Power Panel - Radio Power Supply - 15V | C39: Controls (MCA, train control, er etc) | D39: MCA | E39: 1 | F39: PAC (Brazil, nationalized) | H39: 2534.8867 | I39: 4.247 | J39: High | K39: 85044030 | L39: 12.8x3.8x9.5
A40: 41A240644P2 | B40: HORN MAGNET VALVE | C40: Controls (MCA, train control, er etc) | D40: TRAIN CONTROL | E40: 1 | F40: PAC (Brazil, nationalized) | H40: 2382.3747 | I40: 3.629 | J40: High | K40: 84812090 | L40: 8.4x3.35x7.5
A41: 41A296352CMP387 | B41: ETHERNET CABLE | C41: Controls (MCA, train control, er etc) | D41: MCA | E41: 1 | F41: PAC (Brazil, nationalized) | H41: 2132.2443 | I41: 0.227 | J41: High | K41: 85444200 | L41: 0x0x0
...

Sheet Executive Summary (P&L)
A1: P&L PATHFINDER - REAL PRICE (Material Pricing / Approval Summary methodology)
A3: Exchange Rate (USD->BRL): | B3: 5.1
A4: Total Deal Margin (TDM): | B4: 0.45 | D4: <- editable. Automatically updates Net Price and Client Price below.
A5: PIS/COFINS (blended, real NCM where available): | B5: 0.1006
A6: ICMS: | B6: 0.18
A7: IPI (blended, real NCM where available): | B7: 0.0969
B8: BRL | C8: USD
A9: 1) COST (Raw Cost + TP + Freight + Import Duty)
A10: Raw Cost - Imported Items (BOM USD x Qty x FX) | B10: 1346980.9 | C10: =B10/$B$3
A11: Raw Cost - PAC Items (already nationalized, all-in local cost) | B11: 166060.16 | C11: =B11/$B$3
A12: TP - Transfer Price (13%/17.2% per item group; this is WBT USA's own margin) | B12: 198163.69 | C12: =B12/$B$3
A13: International Freight (real, China Gate quote, 1.23%) | B13: 18998.55 | C13: =B13/$B$3
A14: II - Import Duty (blended 17.96%, real NCM where available) | B14: 280915.82 | C14: =B14/$B$3
A15: Domestic Freight (real, China Gate quote, Santos->Betim/Contagem) | B15: 21753.1 | C15: =B15/$B$3
A16: Supermetal - GDT Integration/Assembly (railcar modification, direct cost) | B16: 707790.6 | C16: =B16/$B$3
A17: FINAL COST (with TP): | B17: =SUM(B10:B16) | C17: =B17/$B$3
A19: 2) MARGIN (TDM applied on cost WITHOUT TP; TP is added back afterwards with no markup)
A20: Base for margin (Final Cost - TP) | B20: =B17-B12 | C20: =B20/$B$3
A21: Net Price w/o TP (Base / (1 - TDM)) | B21: =B20/(1-$B$4) | C21: =B21/$B$3
A22: NET PRICE ('OUR PRICE' - cost + margin, before pass-through taxes): | B22: =B21+B12 | C22: =B22/$B$3
A24: 3) PASS-THROUGH TAXES (do not affect our margin - the client pays, client can credit part of it)
A25: + PIS/COFINS (gross-up, tax-inclusive) | B25: =B22/(1-$B$5) | C25: =B25/$B$3
A26: + ICMS (gross-up, tax-inclusive, stacked on top of PIS/COFINS) | B26: =B25/(1-$B$6) | C26: =B26/$B$3
A27: + IPI (added on top, % of the value already including ICMS) | B27: =B26*$B$7 | C27: =B27/$B$3
A28: FINAL CLIENT PRICE (all taxes included): | B28: =B26+B27 | C28: =B28/$B$3
A30: Notes / Assumptions:
A31: - Methodology: 'Material Pricing' + 'Approval Summary' tabs of Material Pricing.xlsm (P&L Old was discarded - its formulas are broken / #REF!).
A32: - TP is treated as WBT USA's own margin (GM WBT USA); it feeds the cost base but is excluded from WBT Brazil's own margin base (TDM = (TP + GM BRZ) / Net Price).
A33: - International and Domestic Freight: real values from the China Gate import cost quote (Planilha de Custos de Importacao - Pathfinder - Set 26.xlsx), not the old 9%/3% assumptions.
A34: - II/IPI/PIS-COFINS: real per-NCM rate (Material Pricing's 'II' tab) for the 6 priced imported items with a confirmed NCM; worst-case flat rate (our old blended assumption) for the other 41 without one.
A35: - ICMS: flat 18% (same value used in Material Pricing's own real example).
A36: - 88 PAC items are summed as a single block (already an all-in local cost, not decomposed into TP/freight/duty).
A37: - Supermetal's GDT Integration/Assembly cost (railcar refurbishment: lid, door, ladder, harnesses, battery skid, Fastbrake piping, AC, ballast) is included as a direct cost, feeding the same margin base as the equipment - see the 'GDT Integration and Assembly' tab in the main working file for the line-item breakdown.
A38: - 27 items still without a cost quote (Missing) are NOT included in this total - see the Item List tab (Cost Source = MISSING).
A39: - QQP (service taxes) and ISS (tax on the GDT integration/labor rollup) were disregarded for now, as requested.

Sheet Price Calc Detail
A1: PRICE CALCULATION DETAIL - source and formula for every number
A2: Use this tab to answer 'why is this number X' - every line cites its source.
A4: 0) REALITY CHECK vs. US domestic price
A5: US Domestic Reference Price (input - type the real one here): | B5: 900000
A6: Our Price (Net - cost + margin, before Brazilian pass-through taxes): | B6: 945272.43 | C6: <- this is the number that is actually comparable to a US domestic sale (no BR import/consumption tax).
A7: Final Client Price (with all Brazilian taxes): | B7: 1405909.3
A8: Gap vs. US reference (Net Price): | B8: =B6-B5 | C8: =B8/B5
A9: Gap vs. US reference (Final Client Price): | B9: =B7-B5 | C9: =B9/B5
A10: KEY POINT: our Net Price is close to the US reference price - the big jump to the Final Client Price comes entirely from Brazilian
A11: import duty (II) and consumption taxes (IPI/PIS/COFINS/ICMS), which do not exist in a US domestic sale and would apply just the
A12: same whether we import components or a finished, ready-built railcar (a finished vehicle may in fact face a higher/different II bracket -
A13: worth confirming with an auto/rail import specialist before assuming 'buy it finished' avoids this tax cascade).
A15: 1) FULL WATERFALL (matches the 'Executive Summary (P&L)' tab, expanded with sources)
A16: Step | B16: Formula / Logic | C16: BRL | D16: USD | E16: Multiplier vs. Final Cost (subtotals only) | F16: Source / Justification
A17: Raw Cost - Imported Items | B17: BOM USD unit x Qty x FX rate, summed over 47 priced imported items | C17: 1346980.9 | D17: 264113.91 | E17: - | F17: Final Cost List tab, column F (BOM Price USD Unit) x column E (Quantity), FX from Material Pricing.xlsm 'RATES' tab
A18: Raw Cost - PAC Items | B18: Sum of PAC unit cost (BRL) x Qty over 88 PAC-sourced items | C18: 166060.16 | D18: 32560.816 | E18: - | F18: 7-PAC Item Costs.xlsx 'aco_cost' field per item, already a fully-loaded local manufacturing cost (materials+labor+overhead)
A19: TP - Transfer Price | B19: 13% on items that already carried some TP historically; 17.2% on items that had none | C19: 198163.69 | D19: 38855.625 | E19: - | F19: Matheus's directive this session; 17.2%/0% split originally sourced from the color-coded review copy (yellow/green)
A20: International Freight | B20: 1.2295642% of (Raw Cost + TP) | C20: 18998.55 | D20: 3725.2059 | E20: - | F20: 'Planilha de Custos de Importacao - Pathfinder - Set 26.xlsx' (China Gate customs broker quote), Frete+Seguro / Product Value
A21: II - Import Duty | B21: Blended 17.96% on (Raw Cost+TP+Freight): real per-NCM rate for the 6 items with a confirmed NCM, worst-case 18% flat for the other 41 | C21: 280915.82 | D21: 55081.533 | E21: - | F21: Material Pricing.xlsm 'II' tab (real NCM lookup) + our prior flat assumption as fallback
A22: Domestic Freight | B22: Real flat quote for the whole shipment (Santos -> Betim/Contagem, MG) | C22: 21753.1 | D22: 4265.3137 | E22: - | F22: China Gate quote 'Despesas de Importacao' tab: Siscomex, despachante, armazenagem, road transport, Marinha Mercante, etc.
A23: Supermetal - GDT Integration/Assembly | B23: Direct cost: railcar refurbishment (lid, door, ladder, harnesses, battery skid, Fastbrake piping, AC, ballast) | C23: 707790.6 | D23: 138782.47 | E23: - | F23: 'GDT Integration and Assembly' tab, sum of Direct Cost BRL column (18 line items)
A24: FINAL COST (with TP): | C24: 2740662.8 | D24: 537384.87 | E24: 1.000x (baseline)
A26: 2) MARGIN
A27: Base for margin | B27: Final Cost - TP (TP is excluded from our own margin base - it's WBT USA's margin, not ours) | F27: Approval Summary tab of Material Pricing.xlsm: TDM = (TP + GM_BRZ) / Net Price. Algebraically this is equivalent to computing margin on (cost - TP) and adding TP back after, which is what this line does.
A28: Target margin (TDM) | B28: Editable - see the Executive Summary (P&L) tab cell B4 | F28: Matheus's target for this exercise: 45%
A29: NET PRICE ('OUR PRICE'): | C29: 4820889.4 | D29: 945272.43 | E29: 1.759x
A31: 3) PASS-THROUGH TAXES (client pays; do not affect our margin)
A32: PIS/COFINS | B32: Net Price / (1 - 10.06%) - gross-up, blended real-NCM rate | F32: Material Pricing.xlsm 'II' tab (real per-NCM PIS+COFINS) for known items, worst-case 9.25% for the rest
A33: ICMS | B33: Previous subtotal / (1 - 18%) - gross-up, stacked on top of PIS/COFINS | F33: Flat 18%, matches Material Pricing's own worked example. NOT yet validated against the client's specific destination-state ICMS rate (Tabela ICMS / Aliquotas Basicas tabs have the real origin-destination matrix if needed).
A34: IPI | B34: Previous subtotal x blended IPI% - added on top, not a gross-up | F34: Material Pricing.xlsm 'II' tab (real per-NCM IPI) for known items, worst-case 9.75% for the rest
A35: FINAL CLIENT PRICE: | C35: 7170137.3 | D35: 1405909.3 | E35: 2.616x
A37: 4) ASSUMPTIONS REGISTER (challenge a specific input here, not the whole number)
A38: Assumption | B38: Value Used | C38: Confidence | D38: Where it could be wrong
A39: Exchange Rate | B39: 5.10 BRL/USD | C39: Medium | D39: Fixed snapshot from Material Pricing.xlsm; will drift with the real FX on invoice date
A40: TP rate split | B40: 13% / 17.2% | C40: Low-Medium | D40: Arbitrary split chosen this session, not from an official WBT transfer pricing policy document
A41: International Freight | B41: 1.23% of value | C41: High | D41: Real broker quote, but only a simulation per the quote's own disclaimer - confirm with actual booking
A42: Domestic Freight | B42: R$21,753.10 flat | C42: High | D42: Real broker quote for Santos->Betim/Contagem specifically; changes if origin/destination changes
A43: II (Import Duty) | B43: 17.96% blended (6 of 47 imported items on real NCM) | C43: Medium | D43: 41 of 47 imported items still use the worst-case 18% default - no NCM confirmed for them yet
A44: PIS/COFINS | B44: 10.06% blended | C44: Medium | D44: Same NCM-coverage gap as II
A45: IPI | B45: 9.69% blended | C45: Medium | D45: Same NCM-coverage gap as II
...

Sheet Simulation
A1: SIMULATION - what really makes the Pathfinder Iron Ore Car expensive
A2: Change the two yellow switches; the comparison table on the right never depends on them.
A4: SWITCHES
A5: Remove import duty (II) from everything? (1 = yes, 0 = no) | B5: 0
A6: Battery sets (2 = current BOM, 1 = a single set) | B6: 2
A8: BASE VALUES (read from the P&L tab)
A9: Exchange rate | B9: ='Executive Summary (P&L)'!B3
A10: Total Deal Margin (TDM) | B10: ='Executive Summary (P&L)'!B4
A11: PIS/COFINS | B11: ='Executive Summary (P&L)'!B5
A12: ICMS | B12: ='Executive Summary (P&L)'!B6
A13: IPI | B13: ='Executive Summary (P&L)'!B7
A14: US domestic reference price (USD, input) | B14: 900000
A17: SCENARIOS
B18: Selected (switches) - BRL | C18: Selected (switches) - USD | D18: Base (current) - BRL | E18: Base (current) - USD | F18: No import duty (II) - BRL | G18: No import duty (II) - USD | H18: 1 battery set - BRL | I18: 1 battery set - USD | J18: No II + 1 battery set - BRL | K18: No II + 1 battery set - USD
A19: Raw cost - imported items | B19: =$B$48+$C$48*($B$6) | C19: =B19/$B$9 | D19: =$B$48+$C$48*(2) | E19: =D19/$B$9 | F19: =$B$48+$C$48*(2) | G19: =F19/$B$9 | H19: =$B$48+$C$48*(1) | I19: =H19/$B$9 | J19: =$B$48+$C$48*(1) | K19: =J19/$B$9
A20: Raw cost - PAC items | B20: =$B$49 | C20: =B20/$B$9 | D20: =$B$49 | E20: =D20/$B$9 | F20: =$B$49 | G20: =F20/$B$9 | H20: =$B$49 | I20: =H20/$B$9 | J20: =$B$49 | K20: =J20/$B$9
A21: TP - Transfer Price | B21: =$B$50+$C$50*($B$6) | C21: =B21/$B$9 | D21: =$B$50+$C$50*(2) | E21: =D21/$B$9 | F21: =$B$50+$C$50*(2) | G21: =F21/$B$9 | H21: =$B$50+$C$50*(1) | I21: =H21/$B$9 | J21: =$B$50+$C$50*(1) | K21: =J21/$B$9
A22: International freight | B22: =$B$51+$C$51*($B$6) | C22: =B22/$B$9 | D22: =$B$51+$C$51*(2) | E22: =D22/$B$9 | F22: =$B$51+$C$51*(2) | G22: =F22/$B$9 | H22: =$B$51+$C$51*(1) | I22: =H22/$B$9 | J22: =$B$51+$C$51*(1) | K22: =J22/$B$9
A23: II - Import duty | B23: =($B$52+$C$52*($B$6))*(1-($B$5)) | C23: =B23/$B$9 | D23: =($B$52+$C$52*(2))*(1-(0)) | E23: =D23/$B$9 | F23: =($B$52+$C$52*(2))*(1-(1)) | G23: =F23/$B$9 | H23: =($B$52+$C$52*(1))*(1-(0)) | I23: =H23/$B$9 | J23: =($B$52+$C$52*(1))*(1-(1)) | K23: =J23/$B$9
A24: Domestic freight | B24: =$B$53 | C24: =B24/$B$9 | D24: =$B$53 | E24: =D24/$B$9 | F24: =$B$53 | G24: =F24/$B$9 | H24: =$B$53 | I24: =H24/$B$9 | J24: =$B$53 | K24: =J24/$B$9
A25: Supermetal - refurbishment / integration | B25: =$B$54 | C25: =B25/$B$9 | D25: =$B$54 | E25: =D25/$B$9 | F25: =$B$54 | G25: =F25/$B$9 | H25: =$B$54 | I25: =H25/$B$9 | J25: =$B$54 | K25: =J25/$B$9
A26: FINAL COST (with TP): | B26: =SUM(B19:B25) | C26: =B26/$B$9 | D26: =SUM(D19:D25) | E26: =D26/$B$9 | F26: =SUM(F19:F25) | G26: =F26/$B$9 | H26: =SUM(H19:H25) | I26: =H26/$B$9 | J26: =SUM(J19:J25) | K26: =J26/$B$9
A27: Base for margin (Final Cost - TP) | B27: =B26-B21 | C27: =B27/$B$9 | D27: =D26-D21 | E27: =D27/$B$9 | F27: =F26-F21 | G27: =F27/$B$9 | H27: =H26-H21 | I27: =H27/$B$9 | J27: =J26-J21 | K27: =J27/$B$9
A28: Net price w/o TP (Base / (1 - TDM)) | B28: =B27/(1-$B$10) | C28: =B28/$B$9 | D28: =D27/(1-$B$10) | E28: =D28/$B$9 | F28: =F27/(1-$B$10) | G28: =F28/$B$9 | H28: =H27/(1-$B$10) | I28: =H28/$B$9 | J28: =J27/(1-$B$10) | K28: =J28/$B$9
A29: NET PRICE ('OUR PRICE'): | B29: =B28+B21 | C29: =B29/$B$9 | D29: =D28+D21 | E29: =D29/$B$9 | F29: =F28+F21 | G29: =F29/$B$9 | H29: =H28+H21 | I29: =H29/$B$9 | J29: =J28+J21 | K29: =J29/$B$9
A30: + PIS/COFINS (gross-up) | B30: =B29/(1-$B$11) | C30: =B30/$B$9 | D30: =D29/(1-$B$11) | E30: =D30/$B$9 | F30: =F29/(1-$B$11) | G30: =F30/$B$9 | H30: =H29/(1-$B$11) | I30: =H30/$B$9 | J30: =J29/(1-$B$11) | K30: =J30/$B$9
A31: + ICMS (gross-up) | B31: =B30/(1-$B$12) | C31: =B31/$B$9 | D31: =D30/(1-$B$12) | E31: =D31/$B$9 | F31: =F30/(1-$B$12) | G31: =F31/$B$9 | H31: =H30/(1-$B$12) | I31: =H31/$B$9 | J31: =J30/(1-$B$12) | K31: =J31/$B$9
A32: + IPI (on top) | B32: =B31*$B$13 | C32: =B32/$B$9 | D32: =D31*$B$13 | E32: =D32/$B$9 | F32: =F31*$B$13 | G32: =F32/$B$9 | H32: =H31*$B$13 | I32: =H32/$B$9 | J32: =J31*$B$13 | K32: =J32/$B$9
A33: FINAL CLIENT PRICE: | B33: =B31+B32 | C33: =B33/$B$9 | D33: =D31+D32 | E33: =D33/$B$9 | F33: =F31+F32 | G33: =F33/$B$9 | H33: =H31+H32 | I33: =H33/$B$9 | J33: =J31+J32 | K33: =J33/$B$9
A36: WHAT DRIVES THE FINAL CLIENT PRICE (base case)
A37: Removing ALL import duty (II) lowers the Final Client Price by | B37: =D33-F33 | C37: =B37/$B$9
A38: Local output taxes (PIS/COFINS + ICMS + IPI) add on top of Net Price | B38: =D33-D29 | C38: =B38/$B$9
A39: Local taxes are how many times bigger than the II effect? | B39: =B38/B37
A40: Final Client Price with NO II and 1 battery set, vs. US reference | B40: =J33/$B$9 | C40: =B40/$B$14-1
A42: - II (import duty) sits inside the cost, so it is multiplied by the margin (1/(1-TDM)) and then by the local tax cascade - removing it is worth about 2.7x its face value in the final price.
A43: - Even so, the local output taxes (PIS/COFINS, ICMS, IPI) stack on the whole price and outweigh the II effect - that is the point of this tab.
A44: - Battery sets: II, TP and freight of the batteries scale with the quantity; the row values come from the Final Cost List (84A222059P5, group without historical TP -> 17.2%, no confirmed NCM -> II 18%).
A46: BASE VALUES (read from the P&L tab)
B47: Imported items, excluding batteries | C47: Batteries - value per set (current BOM has 2)
A48: Raw cost - imported items | B48: ='Executive Summary (P&L)'!B10-2*C48 | C48: 79995.64
...
