Workbook
Name taxa: [1]Master!$E$1
Name total.itens: [1]Master!$D$112

Sheet Pathfinder
D3: Planilha de Apoio para levantamento de Custos de Importação
B7: Instruções de Preenchimento
B8: 1. Preencha somente os campos em vermelho
B9: 2. Essa planilha serve somente para simulação
B10: 3. Antes de realizar sua importação, contate um despachante aduaneiro de confiança. | H10: PTAX | I10: 46286
B12: 1. Informações Gerais
B14: Razão Social do Importador: | F14: Telefone do Contato
B16: Nome do Fornecedor Internacional | F16: Contato (email, skype, telefone, whatsapp)
B18: Data: | C18: No. Invoice: | D18: Incoterm: | E18: Porto Origem: | F18: Porto Destino: | G18: Agente Cargas: | I18: Versão
B21: 2. Produto/Frete/Seguro (Bloco1) | G21: % | H21: USD | I21: BRL
B22: Taxa Cambial | H22: 1 | I22: 5.15
B23: Nome do Produto | D23: Kit Pathfinder
B24: Custo Unitário do produto (prencher em dólar) | H24: =base!J22 -> 259150.44 | I24: =H24*I22 -> 1334624.8
B25: Quantidade do Produto a ser importada | F25: 1
B26: Valor total dos produtos (na origem) | H26: =H24*F25 -> 259150.44 | I26: =H26*I22 -> 1334624.8
B27: Valor do Frete Internacional (preencher em dólar) (AGENTE DE CARGAS) | H27: =base!I22*1 -> 3055.3182 | I27: =H27*I22 -> 15734.889
B28: Valor do Seguro Internacional (preencher em dólar) | H28: =SUM(H26+H27)*0.05% -> 131.10288 | I28: =H28*I22 -> 675.17983
B29: Sub-Total Bloco 1 Valor Aduaneiro (VMLD) | H29: =H26+H27+H28 -> 262336.86 | I29: =I26+I27+I28 -> 1351034.8
B31: 3. Despesas Aduaneiras (Bloco 2) | G31: % | H31: USD | I31: BRL
B32: (Tx Siscomex, Armazenagem, ARFMM, Desembaraço Aduaneiro, Transporte Local…)
B33: Despesas em dólar | H33: ='Despesas de Importação'!H38 -> 0 | I33: =H33*I22 -> 0
B34: Despesas em Real | H34: =I34/I22 -> 4223.9038 | I34: ='Despesas de Importação'!I38 -> 21753.105
B35: Sub-Total Bloco 2 | H35: =H33+H34 -> 4223.9038 | I35: =I33+I34 -> 21753.105
B37: 4. Impostos Federais (Bloco 3) -- - | G37: % | H37: USD | I37: BRL
B38: II - Imposto Importação | E38: Digite o % aqui ====> | G38: 0.18 | I38: =G38*I29 -> 243186.27
B39: IPI - Imposto Produto Industrializado | E39: Digite o % aqui ====> | G39: 0.0975 | I39: =(I38+I29)*G39 -> 155436.56
B40: PIS - Programa Integração Social | E40: Digite o % aqui ====> | G40: 0.021 | I40: =I29*G40 -> 28371.732
B41: Cofins - Contrib. Financ. Seguridade Social | E41: Digite o % aqui ====> | G41: 0.1025 | I41: =I29*G41 -> 138481.07
B42: Sub-Total do Bloco 3 | G42: =I42/I29 -> 0.41855 | H42: =SUM(H38:H41) -> 0 | I42: =SUM(I38:I41) -> 565475.64
B44: 5. Impostos Estaduais (ICMS) Bloco 4 | G44: % | H44: USD | I44: BRL
B45: ICMS - Imp. Circ. Merc. Serv. | E45: Digite o % aqui ====> | G45: 0.18 | H45: =I45/I22 -> 81688.82 | I45: =SUM((I29+I38+I39+I40+I41)/0.82)*G45 -> 420697.42
B46: Sub-Total do Bloco 4 (ICMS a pagar) | G46: =I46/I29 -> 0.31138902 | I46: =I45 -> 420697.42
B48: Resumo da Operação | G48: % | H48: USD | I48: BRL
B49: Valor dos produtos | G49: =I49/I49 -> 1 | I49: =I26 -> 1334624.8
B50: Valor do Frete Int´l + Seguro | G50: =I50/I$49 -> 0.012295642 | I50: =I27+I28 -> 16410.069
B51: Valor das Despesas | G51: =I51/I$49 -> 0.016299042 | I51: =I35 -> 21753.105
B52: Valor dos Impostos (Apenas II) | G52: =I52/I$49 -> 0.18221322 | I52: =I38 -> 243186.27
B53: Valor Total da Importação | F53: Fator Conversão => | G53: =I53/I$49 -> 1.2108079 | I53: =I49+I50+I51+I52 -> 1615974.2
B56: Valor Total da Importação (TODOS IMPOSTOS) | F56: Fator Conversão => | G56: =I56/I$49 -> 1.7675088 | I56: =I49+I50+I51+I52+I39+I40+I41+I45 -> 2358961
B58: CUSTO UNITÁRIO SOMENTE COM II | I58: =I53/$F$25 -> 1615974.2
...

Sheet Despesas de Importação
D3: Planilha de Apoio para levantamento de Custos de Importação
B7: Instruções de Preenchimento
B8: 1. Preencha somente os campos em vermelho
B9: 2. Essa planilha serve somente para simulação
B10: 3. Antes de realizar sua importação, contate um despachante aduaneiro de confiança.
B12: 3. Despesas de Importação (Detalhamento) | H12: USD | I12: BRL
H13: Preencher umas das duas opções, ou em Dólar ou em Reais, nunca as duas na mesma linha
B14: 1. Siscomex | I14: 165
B15: 2. Despachante Aduaneiro | I15: 430
B16: 3. Armazenagem Santos Brasil | I16: =Pathfinder!I29*0.4% -> 5404.1394
B17: 4. Transporte Rodoviário (SSZ x Betim) | I17: =SUM(11000/10000)*3000 -> 3300
B18: 4.1 Transporte Rodoviário (BetimX Contagem) | I18: 1500
B19: 5. Marinha Mercante 8% DO VALOR DO FRETE | I19: =Pathfinder!I27*8% -> 1258.7911
B20: 6. Alteração de BL
B21: 7. Confecção de BL | I21: 650
B22: 8. Sindicado dos Despachantes
B23: 9. Capatazia / Movimentação | I23: 600
B24: 10. Confecção de LI
B25: 11. Anuência de LI
B26: 12. Liberação de DTA | I26: 290
B27: 13. Armazenagem BETIM | I27: =SUM(Pathfinder!I29*0.5%) -> 6755.1742
B28: 14. Desconsolidação | I28: 850
B29: 15. Liberação de B/L + Desconsolidação | I29: 550
B30: 16. Collect fee
B31: 17. Contratos de Cambio
B32: 18. IOF | E32: Sempre
B33: 19. Laudos e Inspeções
B34: 20. Fumigação
B35: 21. Consultoria
B36: 23. Courrier
B37: 24. Outros
B38: Total das Despesas | H38: =SUM(H14:H37) -> 0 | I38: =SUM(I14:I37) -> 21753.105
B41: 1. Valores sujeitos a alteração cambial
B44: Observações Importantes:
B45: 1. Os custos de importação tem muitas variáveis, então não existe um padrão único. O custo exato da sua importação deve
B46: ser feito por um profissional da área (despachante aduaneiro ou analista de importação).
B47: 2. Essa planilha serve para você ter uma noção se o produto é viável ou não, sendo que ela não apresenta o custo exato da
B48: sua importação. Não pelos cálculos e fórmulas, mas provavelmente pela precisão das informações que você está inserindo.
B49: 3. No entanto, com as informações obtidas nessa planilha você poderá ter noção sobre a viabilidade do produto e decidir
B50: se vai importar ou não (esse é o objetivo agora)
...

Sheet base
B3: PN | C3: DESCRIPTION | D3: NCM | E3: PESO (KG) | F3: QTY | G3: Price EA USD | I3: PESO BRUTO (EST) | J3: VALOR FOB TOTAL (EST) | L3: II (%) | M3: IPI (%) | N3: PIS (%) | O3: COFINS (%)
B4: 41A296352CMP437 | C4: Dual Processor Module (DPM)+ LXA (Distributed Power Radio) | D4: 90328990 | E4: 4.536 | F4: 1 | G4: 63100.819 | I4: =SUM(E4*F4)*1.1 -> 4.9896 | J4: =SUM(F4*G4) -> 63100.819 | L4: 18 | M4: 9.75 | N4: 2.1 | O4: 10.25
B5: 84A222059P5 | C5: BATTERIES | D5: 90328990 | E5: =2500*0.4536 -> 1134 | F5: 2 | G5: 15685.42 | I5: =SUM(E5*F5)*1.1 -> 2494.8 | J5: =SUM(F5*G5) -> 31370.84 | L5: 18 | M5: 9.75 | N5: 2.1 | O5: 10.25
B6: 41A296352LUG24 | C6: CSX Antenna Enclosure Arrangement | D6: 90328990 | E6: 136.078 | F6: 1 | G6: 30000 | I6: =SUM(E6*F6)*1.1 -> 149.6858 | J6: =SUM(F6*G6) -> 30000 | L6: 18 | M6: 9.75 | N6: 2.1 | O6: 10.25
B7: 37495P | C7: KIT ETMS VIRGIN TRAINS FEC EVO44 | D7: 90328990 | E7: 45.359 | F7: 1 | G7: 28529 | I7: =SUM(E7*F7)*1.1 -> 49.8949 | J7: =SUM(F7*G7) -> 28529 | L7: 18 | M7: 9.75 | N7: 2.1 | O7: 10.25
B8: 84A215295P62 | C8: Pneumatic Brake Control System (Including lament and control portions) Includes EM EAB Control Functionality | D8: 90328990 | E8: 134.263 | F8: 1 | G8: 23409.1 | I8: =SUM(E8*F8)*1.1 -> 147.6893 | J8: =SUM(F8*G8) -> 23409.1 | L8: 18 | M8: 9.75 | N8: 2.1 | O8: 10.25
B9: 41A296352DNP37 | C9: RADIO PRAD PTC RADIO | D9: 90328990 | E9: 9.616 | F9: 1 | G9: 20000 | I9: =SUM(E9*F9)*1.1 -> 10.5776 | J9: =SUM(F9*G9) -> 20000 | L9: 18 | M9: 9.75 | N9: 2.1 | O9: 10.25
B10: 17FM878A6 | C10: NIO 2.0 | D10: 90328990 | E10: 25.854 | F10: 3 | G10: 5176.9118 | I10: =SUM(E10*F10)*1.1 -> 85.3182 | J10: =SUM(F10*G10) -> 15530.735 | L10: 18 | M10: 9.75 | N10: 2.1 | O10: 10.25
B11: L7000083-900 | C11: Wireless Communications Management Module, Gen 3 (WCM3)​ | D11: 90328990 | E11: 4.536 | F11: 2 | G11: 5000 | I11: =SUM(E11*F11)*1.1 -> 9.9792 | J11: =SUM(F11*G11) -> 10000 | L11: 18 | M11: 9.75 | N11: 2.1 | O11: 10.25
B12: 84A237085AEP121 | C12: 8 Slot ACC Chassis for MCA w/ i7 HPEAP and SMM2 Cards | D12: 90328990 | E12: 9.072 | F12: 1 | G12: 8000 | I12: =SUM(E12*F12)*1.1 -> 9.9792 | J12: =SUM(F12*G12) -> 8000 | L12: 18 | M12: 9.75 | N12: 2.1 | O12: 10.25
B13: 17KC108E28 | C13: MASTER CONTROLLER | D13: 90328990 | E13: 25.855 | F13: 1 | G13: 5877.102 | I13: =SUM(E13*F13)*1.1 -> 28.4405 | J13: =SUM(F13*G13) -> 5877.102 | L13: 18 | M13: 9.75 | N13: 2.1 | O13: 10.25
B14: 84A215295P73 | C14: Air Brake Handle Assembly (AAR Console) | D14: 90328990 | E14: 7.938 | F14: 1 | G14: 5702.83 | I14: =SUM(E14*F14)*1.1 -> 8.7318 | J14: =SUM(F14*G14) -> 5702.83 | L14: 18 | M14: 9.75 | N14: 2.1 | O14: 10.25
B15: 17FM868B2 | C15: SNIO | D15: 90328990 | E15: 4.99 | F15: 1 | G15: 4150.9559 | I15: =SUM(E15*F15)*1.1 -> 5.489 | J15: =SUM(F15*G15) -> 4150.9559 | L15: 18 | M15: 9.75 | N15: 2.1 | O15: 10.25
B16: 41A296352DNP55 | C16: VOICE RADIO RITRON | D16: 90328990 | E16: 7.575 | F16: 1 | G16: 3933 | I16: =SUM(E16*F16)*1.1 -> 8.3325 | J16: =SUM(F16*G16) -> 3933 | L16: 18 | M16: 9.75 | N16: 2.1 | O16: 10.25
B17: 32613P | C17: KIT ETMS AXLE INTERFACE FOR WPart Number 29266P | D17: 90328990 | E17: 4.536 | F17: 1 | G17: 2981.71 | I17: =SUM(E17*F17)*1.1 -> 4.9896 | J17: =SUM(F17*G17) -> 2981.71 | L17: 18 | M17: 9.75 | N17: 2.1 | O17: 10.25
B18: 41B546155P2 | C18: Horn | D18: 90328990 | E18: 4.536 | F18: 1 | G18: 1891.99 | I18: =SUM(E18*F18)*1.1 -> 4.9896 | J18: =SUM(F18*G18) -> 1891.99 | L18: 18 | M18: 9.75 | N18: 2.1 | O18: 10.25
C19: Ditchlight Control Box (SMART BOX-V3-DLC ) | D19: 90328990 | E19: 4.536 | F19: 2 | G19: 800 | I19: =SUM(E19*F19)*1.1 -> 9.9792 | J19: =SUM(F19*G19) -> 1600 | L19: 18 | M19: 9.75 | N19: 2.1 | O19: 10.25
B20: 41D758679BJG16 84D704379AFG1 | C20: EC Part NumberL ASM | D20: 90328990 | E20: 4.99 | F20: 1 | G20: 1572.36 | I20: =SUM(E20*F20)*1.1 -> 5.489 | J20: =SUM(F20*G20) -> 1572.36 | L20: 18 | M20: 9.75 | N20: 2.1 | O20: 10.25
C21: LED Ditch Light | D21: 90328990 | E21: 3.628 | F21: 4 | G21: 375 | I21: =SUM(E21*F21)*1.1 -> 15.9632 | J21: =SUM(F21*G21) -> 1500 | L21: 18 | M21: 9.75 | N21: 2.1 | O21: 10.25
I22: =SUM(I4:I21) -> 3055.3182 | J22: =SUM(J4:J21) -> 259150.44
