Workbook

Sheet Executive Summary (GDT Project)
A1: EXECUTIVE SUMMARY - MRS PATHFINDER GDT RAILCAR PROPOSAL
A2: Exchange Rate: | B2: USD 1.00 = BRL 5.16
A3: Profit Margin (%): | B3: 0.45 | C3: <- editable input. Change this to update the sale price table below.
A5: 1) COST / PURE BREAKEVEN (initial Pathfinder price, no margin)
A6: Project Module | B6: Cost BRL (Excl. Taxes) | C6: Cost USD (Excl. Taxes) | D6: Cost BRL (Incl. Taxes) | E6: Cost USD (Incl. Taxes) | F6: % of Total
A7: 1. Equipment & Components (BOM Pathfinder + SKID) | B7: =SUM('Final Cost List'!K2:K163) | C7: 350000 | D7: =SUM('Final Cost List'!L2:L163) | E7: =SUM('Final Cost List'!J2:J163) | F7: =B7/$B$9
A8: 2. Adaptation, Container & Labor (Rollup GDT) | B8: =SUM('GDT Integration and Assembly'!C2:C18) | C8: =SUM('GDT Integration and Assembly'!D2:D18) | D8: =SUM('GDT Integration and Assembly'!E2:E18) | E8: =SUM('GDT Integration and Assembly'!F2:F18) | F8: =B8/$B$9
A9: TOTAL CONSOLIDATED GDT RAILCAR PROJECT (COST) | B9: =SUM(B7:B8) | C9: =SUM(C7:C8) | D9: =SUM(D7:D8) | E9: =SUM(E7:E8) | F9: 1
A11: 2) SALE PRICE WITH PROFIT MARGIN (driven by cell B3)
A12: Project Module | B12: Sale Price BRL (Excl. Taxes) | C12: net Price USD (Excl. Taxes) | D12: Sale Price BRL (Incl. Taxes) | E12: Sale Price USD (Incl. Taxes) | F12: % of Total
A13: 1. Equipment & Components (BOM Pathfinder + SKID) | B13: =B7*(1+$B$3) | C13: =C7/(1-$B$3) | D13: =D7*(1+$B$3) | E13: =E7*(1+$B$3) | F13: =B13/$B$15
A14: 2. Adaptation, Container & Labor (Rollup GDT) | B14: =B8*(1+$B$3) | C14: =C8/(1-$B$3) | D14: =D8*(1+$B$3) | E14: =E8*(1+$B$3) | F14: =B14/$B$15
A15: TOTAL CONSOLIDATED GDT RAILCAR PROJECT (SALE PRICE) | B15: =SUM(B13:B14) | C15: =SUM(C13:C14) | D15: =SUM(D13:D14) | E15: =SUM(E13:E14) | F15: 1

Sheet Final Cost List
A1: Part Number | B1: Description | C1: System | D1: SubSystem | E1: Quantity | F1: BOM Price (USD Unit) | G1: Final Unit Price USD (Excluding Taxes) | H1: Final Total Price USD (Excluding Taxes) | I1: Final Unit Price USD (Including Taxes) | J1: Final Total Price USD (Including Taxes) | K1: Total Price BRL (Excluding Taxes) | L1: Total Price BRL (Including Taxes) | M1: PAC Price (BRL Unit) | N1: BOM Price (USD Unit) | O1: Cost Source | P1: Status / Notes | R1: Simple Item Category | S1: Nationalization Status | T1: Import Scenario (BOM+TP+Freight+Duty, BRL Incl. Tax) | U1: Nationalized/PAC Price (BRL Incl. Tax) | V1: Cheaper Option | W1: Peso (kg) | X1: NCM | Y1: Dimensions (C x A x L, in) | Z1: Weight Data Source | AA1: Peso - Confidence
A2: 41A296352CMP437 | B2: Dual Processor Module (DPM)+ LXA (Distributed Power Radio) | C2: Controls (MCA, train control, er etc) | D2: LXA | E2: 1 | F2: 63100.819 | G2: 96312.869 | H2: 96312.869 | I2: 120602.14 | J2: 120602.14 | K2: 496974.41 | L2: 622307.04 | O2: Imported BOM (USA) | P2: TP included; international freight updated to 9% | W2: 4.536 | X2: 90328990 | Z2: Engineering weight (Harland Updated Weights.xlsx) | AA2: High
A3: 37495P | B3: KIT ETMS VIRGIN TRAINS FEC EVO44 | C3: PTC | D3: PTC KIT MASTER | E3: 1 | F3: 28529 | G3: 43544.757 | H3: 43544.757 | I3: 54526.368 | J3: 54526.368 | K3: 224690.95 | L3: 281356.06 | O3: Imported BOM (USA) | P3: Direct supplier purchase; TP excluded; international freight 9% | W3: 45.359 | Z3: Engineering weight (Harland Updated Weights.xlsx) | AA3: High
A4: 84A222059P5 | B4: BATTERIES | C4: Power | D4: POWER | E4: 2 | F4: 15685.42 | G4: 20427.624 | H4: 40855.249 | I4: 25579.294 | J4: 51158.589 | K4: 210813.08 | L4: 263978.32 | O4: Imported BOM (USA) | P4: TP included; international freight updated to 9% | W4: 1123.095 | Z4: Engineering weight (Harland Updated Weights.xlsx) | AA4: High
A5: 41A296352LUG24 | B5: CSX Antenna Enclosure Arrangement | C5: Connectivity | D5: ANTENNA KIT Master | E5: 1 | F5: 30000 | G5: 39069.96 | H5: 39069.96 | I5: 48923.065 | J5: 48923.065 | K5: 201600.99 | L5: 252443.02 | O5: Imported BOM (USA) | P5: TP included; international freight updated to 9% | W5: 136.078 | Z5: Engineering weight (Harland Updated Weights.xlsx) | AA5: High
A6: 84A215295P62 | B6: Pneumatic Brake Control System (Including lament and control portions) Includes EM EAB Control Functionality | C6: Air | D6: Fastbrake | E6: 1 | F6: 23409.1 | G6: 35730.084 | H6: 35730.084 | I6: 44740.902 | J6: 44740.902 | K6: 184367.23 | L6: 230863.05 | O6: Imported BOM (USA) | P6: Direct supplier purchase; TP excluded; international freight 9% | W6: 134.263 | Z6: Engineering weight (Harland Updated Weights.xlsx) | AA6: High
A7: 41A296352DNP37 | B7: RADIO PRAD PTC RADIO | C7: PTC | D7: PTC | E7: 1 | F7: 20000 | G7: 26046.64 | H7: 26046.64 | I7: 32615.377 | J7: 32615.377 | K7: 134400.66 | L7: 168295.34 | O7: Imported BOM (USA) | P7: Direct supplier purchase; TP excluded; international freight 9% | W7: 9.616 | Z7: Engineering weight (Harland Updated Weights.xlsx) | AA7: High
A8: 17FM878A6 | B8: NIO 2.0 | C8: Controls (MCA, train control, er etc) | D8: MCA | E8: 3 | F8: 5176.9118 | G8: 6742.0579 | H8: 20226.174 | I8: 8442.3465 | J8: 25327.039 | K8: 104367.06 | L8: 130687.52 | O8: Imported BOM (USA) | P8: TP included; international freight updated to 9% | W8: 8.618 | Z8: Engineering weight (Harland Updated Weights.xlsx) | AA8: High
A9: L7000083-900 | B9: Wireless Communications Management Module, Gen 3 (WCM3)​ | C9: Controls (MCA, train control, er etc) | D9: TRAIN CONTROL | E9: 2 | F9: 5000 | G9: 7631.6655 | H9: 15263.331 | I9: 9556.3054 | J9: 19112.611 | K9: 78758.788 | L9: 98621.072 | O9: Imported BOM (USA) | P9: Made by GET; retained for GET impact analysis | R9: Wire/Cable | S9: Low confidence - no comparable PAC item found | T9: 98621.072 | U9: 7609.408 | V9: PAC/National is cheaper (by R$ 91,011.66) | W9: 2.268 | Z9: Engineering weight (Harland Updated Weights.xlsx) | AA9: High
A10: 84A237085AEP121 | B10: 8 Slot ACC Chassis for MCA w/ i7 HPEAP and SMM2 Cards | C10: Controls (MCA, train control, er etc) | D10: TRAIN CONTROL | E10: 1 | F10: 8000 | G10: 12210.665 | H10: 12210.665 | I10: 15290.089 | J10: 15290.089 | K10: 63007.031 | L10: 78896.858 | O10: Imported BOM (USA) | P10: TP included; international freight updated to 9% | W10: 9.072 | Z10: Engineering weight (Harland Updated Weights.xlsx) | AA10: High
A11: 17FL472A2 | B11: TMC PANEL | C11: SKID Assembly | D11: SKID (Skid) | E11: 1 | H11: 11326.967 | I11: 14183.531 | J11: 14183.531 | K11: 58447.152 | L11: 73187.017 | M11: 58447.152 | O11: PAC (Brazil BRL) | P11: Direct supplier purchase; TP excluded; international freight 9% | W11: 20.412 | X11: 85371090 | Z11: Engineering weight (Harland Updated Weights.xlsx) | AA11: High
A12: 17KC108E28 | B12: MASTER CONTROLLER | C12: Controls (MCA, train control, er etc) | D12: TRAIN CONTROL | E12: 1 | F12: 5877.102 | H12: 9464.1997 | I12: 11850.989 | J12: 11850.989 | K12: 48835.27 | L12: 61151.102 | O12: GET | P12: TP included; international freight updated to 9% | W12: 25.855 | Z12: Engineering weight (Harland Updated Weights.xlsx) | AA12: High
A13: 84A215295P73 | B13: Air Brake Handle Assembly (AAR Console) | C13: Air | D13: Fastbrake | E13: 1 | F13: 5702.83 | G13: 8704.4182 | H13: 8704.4182 | I13: 10899.597 | J13: 10899.597 | K13: 44914.798 | L13: 56241.921 | O13: Imported BOM (USA) | P13: Direct supplier purchase; TP excluded; international freight 9% | W13: 7.938 | Z13: Engineering weight (Harland Updated Weights.xlsx) | AA13: High
A14: 17FM868B2 | B14: SNIO | C14: Controls (MCA, train control, er etc) | D14: MCA | E14: 1 | F14: 4150.9559 | G14: 5405.9227 | H14: 5405.9227 | I14: 6769.2496 | J14: 6769.2496 | K14: 27894.561 | L14: 34929.328 | O14: Imported BOM (USA) | P14: Direct supplier purchase; TP excluded; international freight 9% | W14: 4.99 | Z14: Engineering weight (Harland Updated Weights.xlsx) | AA14: High
A15: 41A296352DNP55 | B15: VOICE RADIO RITRON | C15: Connectivity | D15: VOICE RADIO | E15: 1 | F15: 3933 | G15: 5122.0718 | H15: 5122.0718 | I15: 6413.8139 | J15: 6413.8139 | K15: 26429.89 | L15: 33095.28 | O15: Imported BOM (USA) | P15: TP included; international freight updated to 9% | W15: 7.575 | Z15: Engineering weight (Harland Updated Weights.xlsx) | AA15: High
A16: 32613P | B16: KIT ETMS AXLE INTERFACE FOR WPart Number 29266P | C16: PTC | D16: PTC | E16: 1 | F16: 2981.71 | G16: 4551.0827 | H16: 4551.0827 | I16: 5698.8263 | J16: 5698.8263 | K16: 23483.587 | L16: 29405.944 | O16: Imported BOM (USA) | P16: Direct supplier purchase; TP excluded; international freight 9% | W16: 4.536 | Z16: Engineering weight (Harland Updated Weights.xlsx) | AA16: High
A17: 17FH40X1 | B17: LPS 17FH40 (COMMON LOGIC POWER SUPPLY) (5v, 15v, 19v, 24v) | C17: POWER | D17: POWER SUPPLY | E17: 1 | H17: 2915.0271 | I17: 3650.1717 | J17: 3650.1717 | K17: 15041.54 | L17: 18834.886 | M17: 15041.54 | O17: PAC (Brazil BRL) | P17: Brazilian factory PAC price (local Brazilian cost) | W17: 18.144 | X17: 85044029 | Y17: 24x10x20 | Z17: Engineering weight (Harland Updated Weights.xlsx) | AA17: High
A18: 41D758679BJG16 84D704379AFG1 | B18: EC Part NumberL ASM | C18: Power | D18: Circuit Breaker | E18: 1 | F18: 1572.36 | H18: 2532.0522 | I18: 3170.6138 | J18: 3170.6138 | K18: 13065.389 | L18: 16360.367 | O18: GET | P18: Made by GET; retained for GET impact analysis | W18: 4.99 | X18: 86079100 | Y18: 20x3.5x25.5 | Z18: Exact PN match in item catalog (84D704379AFG1) | AA18: High
A19: 41B546155P2 | B19: Horn | C19: Controls (MCA, train control, er etc) | D19: TRAIN CONTROL | E19: 1 | F19: 1891.99 | G19: 2463.9991 | H19: 2463.9991 | I19: 3085.3983 | J19: 3085.3983 | K19: 12714.235 | L19: 15920.655 | O19: Imported BOM (USA) | P19: Brazilian factory PAC price (local Brazilian cost) | W19: 4.536 | Z19: Engineering weight (Harland Updated Weights.xlsx) | AA19: High
B20: Ditchlight Control Box (SMART BOX-V3-DLC ) | C20: Controls (MCA, train control, er etc) | D20: TRAIN CONTROL | E20: 2 | F20: 800 | G20: 1221.0665 | H20: 2442.133 | I20: 1529.0089 | J20: 3058.0177 | K20: 12601.406 | L20: 15779.372 | O20: Imported BOM (USA) | P20: Brazilian factory PAC price (local Brazilian cost) | W20: 2.268 | Z20: Engineering weight (Harland Updated Weights.xlsx) | AA20: High
B21: LED Ditch Light | C21: Controls (MCA, train control, er etc) | D21: TRAIN CONTROL | E21: 4 | F21: 375 | G21: 572.37491 | H21: 2289.4997 | I21: 716.72291 | J21: 2866.8916 | K21: 11813.818 | L21: 14793.161 | O21: Imported BOM (USA) | P21: TP included; international freight updated to 9% | W21: 0.907 | Z21: Engineering weight (Harland Updated Weights.xlsx) | AA21: High
A22: 17FM839B1 | B22: PANEL ASM CFD - Thin Client Display | C22: Controls (MCA, train control, er etc) | D22: MCA | E22: 1 | H22: 2248.7824 | I22: 2815.9058 | J22: 2815.9058 | K22: 11603.717 | L22: 14530.074 | M22: 11603.717 | O22: PAC (Brazil BRL) | P22: Made by GET; retained for GET impact analysis | W22: 9.299 | X22: 85312000 | Y22: 18.5x8.5x15 | Z22: Exact PN match in item catalog (17FM839B1) | AA22: High
A23: 17FM839A3 | B23: TCD (Thin Client Display) | C23: SKID Assembly | D23: SKID (Skid) | E23: 1 | H23: 2248.7824 | I23: 2815.9058 | J23: 2815.9058 | K23: 11603.717 | L23: 14530.074 | M23: 11603.717 | O23: PAC (Brazil BRL) | P23: Direct supplier purchase; TP excluded; international freight 9% | W23: 9.299 | X23: 85312000 | Y23: 18.5x8.5x15 | Z23: ESTIMATE (medium confidence) - Same physical item as 17FM839B1 (already priced as such) | AA23: High
A24: 84A201003DAP1 | B24: ELECTRIC Bell | C24: Controls (MCA, train control, er etc) | D24: TRAIN CONTROL | E24: 1 | H24: 1839.4297 | I24: 2303.3179 | J24: 2303.3179 | K24: 9491.4571 | L24: 11885.12 | M24: 9491.4571 | O24: PAC (Brazil BRL) | P24: TP included; international freight updated to 9% | W24: 8.119 | X24: 85318000 | Y24: 14.25x14.25x10 | Z24: Exact PN match in item catalog (84A201003DAP1) | AA24: High
A25: 17FB193E2F | B25: GET Card | C25: GET | D25: GET Card | E25: 1 | H25: 1792.8535 | I25: 2244.9956 | J25: 2244.9956 | K25: 9251.1239 | L25: 11584.177 | M25: 9251.1239 | O25: PAC (Brazil BRL) | P25: Made by GET; retained for GET impact analysis | W25: 1.114 | X25: 85049040 | Y25: 17.2x1.95x11.2 | Z25: Exact PN match in item catalog (17FB193E2F) | AA25: High
A26: 84A215295P3 | B26: POU-to-Handle cable 18' length | C26: Air | D26: Fastbrake | E26: 1 | F26: 1036.89 | G26: 1582.6395 | H26: 1582.6395 | I26: 1981.7675 | J26: 1981.7675 | K26: 8166.42 | L26: 10225.92 | O26: Imported BOM (USA) | P26: TP included; international freight updated to 9% | R26: Wire/Cable | S26: Low confidence - PAC family match, different length | T26: 10225.92 | U26: 8409.4743 | V26: PAC/National is cheaper (by R$ 1,816.45) | W26: 1.247 | Z26: ESTIMATE (medium confidence) - Estimate from same-PN-family 84A215295P37 (Handle Junction Box) | AA26: Medium
A27: 41B566322ACG1 | B27: TRAINLINE RESISTOR PANEL | C27: SKID Assembly | D27: Controls (MCA, train control, er etc) | E27: 1 | H27: 1306.7417 | I27: 1636.2907 | J27: 1636.2907 | K27: 6742.7873 | L27: 8443.2599 | M27: 6742.7873 | O27: GET | P27: TP included; international freight updated to 9% | W27: 2.859 | X27: 85333990 | Y27: 14x6x8.5 | Z27: Exact PN match in item catalog (41B566322ACG1) | AA27: High
A28: 41A296304DDP4 | B28: G-RECTIFIER POWER BLOCK | C28: SKID Assembly | D28: Controls (MCA, train control, er etc) | E28: 20 | H28: 1264.4303 | I28: 79.16543 | J28: 1583.3086 | K28: 6524.4601 | L28: 8169.8724 | M28: 326.22301 | O28: PAC (Brazil BRL) | P28: Brazilian factory PAC price (local Brazilian cost) | W28: 0.054 | X28: 85411099 | Y28: 10.85x1.1x8.5 | Z28: Exact PN match in item catalog (41A296304DDP4) - FLAGGED: Exact PN match, but 0.054 kg is implausibly light for a 'Rectifier Power Block' - catalog weight likely covers only a sub-component. Do not use for freight without verification. | AA28: Low
A29: RCCR-RMTCBL-RA-CUSTOM | B29: VOICE RADIO RITRON CABLE,REMOTE,RR-225/XXX, RCCR,RIGHT ANGLE,19-PIN,FLAME RETARDANT | C29: Connectivity | D29: VOICE RADIO | E29: 1 | F29: 761 | G29: 991.07465 | H29: 991.07465 | I29: 1241.0151 | J29: 1241.0151 | K29: 5113.9452 | L29: 6403.6379 | O29: Imported BOM (USA) | P29: Brazilian factory PAC price (local Brazilian cost) | R29: Wire/Cable | S29: Low confidence - no comparable PAC item found | T29: 6403.6379 | U29: 3569.0421 | V29: PAC/National is cheaper (by R$ 2,834.60)
A30: 41C663693G1 | B30: PANEL CPF | C30: Power | D30: POWER | E30: 1 | H30: 924.61033 | I30: 1157.789 | J30: 1157.789 | K30: 4770.9893 | L30: 5974.1915 | M30: 4770.9893 | O30: GET | P30: Brazilian factory PAC price (local Brazilian cost) | W30: 5.761 | X30: 85371090 | Y30: 20.5x10.5x11.5 | Z30: Exact PN match in item catalog (41C663693G1) | AA30: High
A31: 41A296352PTP306/41A296352PTP122 | B31: Assembled Air Manifold (Contains 3 pressure sensors mounted in appropriate locations on Air Manifold.) | C31: PTC | D31: PTC | E31: 1 | F31: 595.7889 | G31: 909.37232 | H31: 909.37232 | I31: 1138.7081 | J31: 1138.7081 | K31: 4692.3612 | L31: 5875.734 | O31: Imported BOM (USA) | P31: Brazilian factory PAC price (local Brazilian cost) | W31: 5.897 | X31: 85381000 | Z31: ESTIMATE (medium confidence) - Estimate from similar item 41C619972P3 (Air Brake Manifold) | AA31: Medium
A32: 84A232147P1 | B32: KNOB HLD DWN with washer and screw | C32: Controls (MCA, train control, er etc) | D32: TRAIN CONTROL | E32: 30 | H32: 741.13821 | I32: 30.934895 | J32: 928.04685 | K32: 3824.2732 | L32: 4788.7217 | M32: 127.47577 | O32: PAC (Brazil BRL) | P32: Brazilian factory PAC price (local Brazilian cost) | W32: 0.045 | X32: 83024900 | Y32: 3.5x0.75x0.75 | Z32: Exact PN match in item catalog (84A232147P1) | AA32: High
A33: 32447P | B33: ASY CABLE WHEEL TACH AC EVO/SD70 ACE | C33: PTC | D33: PTC | E33: 1 | F33: 411.22 | G33: 627.6587 | H33: 627.6587 | I33: 785.94878 | J33: 785.94878 | K33: 3238.7189 | L33: 4055.4957 | O33: Imported BOM (USA) | P33: Calculated with TP (17.2%) + International Freight (15%) + Import Duty (16%) + Domestic Freight (3%) | Qtd=1.0 | R33: Wire/Cable | S33: High confidence PAC match (exact desc, PN 29707P) - not yet applied | T33: 4055.4957 | U33: 373.6982 | V33: PAC/National is cheaper (by R$ 3,681.80)
A34: 41A296352PTP10/319/34 | B34: VALVE Part NumberEUMATIC NC/CO (Penalty Magnet Valve) Graham-White 812-142 | C34: PTC | D34: PTC | E34: 1 | F34: 404.6239 | G34: 617.59085 | H34: 617.59085 | I34: 773.34191 | J34: 773.34191 | K34: 3186.7688 | L34: 3990.4443 | O34: Imported BOM (USA) | P34: Brazilian factory PAC price (local Brazilian cost)
A35: 84A201176P1 | B35: Pathfinder Control Unit Connector (MU Plug) | C35: Controls (MCA, train control, er etc) | D35: TRAIN CONTROL | E35: 2 | H35: 573.97817 | I35: 359.36524 | J35: 718.73049 | K35: 2961.7273 | L35: 3708.6493 | M35: 1480.8637 | O35: PAC (Brazil BRL) | P35: Calculated with TP (17.2%) + International Freight (15%) + Import Duty (16%) + Domestic Freight (3%) | Qtd=1.0 | R35: Connector/Plug | S35: Already nationalized (PAC) | T35: 4406.427 | U35: 3708.6493 | V35: PAC/National is cheaper (by R$ 697.78) | W35: 2.404 | X35: 85366990 | Y35: 7x4x7 | Z35: Exact PN match in item catalog (84A201176P1) | AA35: High
A36: 84A201150ACP2 | B36: CROSSING BELL PUSH BUTTON SWITCH | C36: Controls (MCA, train control, er etc) | D36: TRAIN CONTROL | E36: 1 | H36: 551.04203 | I36: 690.01005 | J36: 690.01005 | K36: 2843.3769 | L36: 3560.4519 | M36: 2843.3769 | O36: PAC (Brazil BRL) | P36: Calculated with TP (17.2%) + International Freight (15%) + Import Duty (16%) + Domestic Freight (3%) | Qtd=1.0 | W36: 0.411 | X36: 85365090 | Y36: 11.8x6.4x8.05 | Z36: Exact PN match in item catalog (84A201150ACP2) | AA36: High
A37: 17FH37A6 | B37: RPS Power Panel - Radio Power Supply - 15V | C37: Controls (MCA, train control, er etc) | D37: MCA | E37: 1 | H37: 491.25711 | I37: 615.14789 | J37: 615.14789 | K37: 2534.8867 | L37: 3174.1631 | M37: 2534.8867 | O37: PAC (Brazil BRL) | P37: Brazilian factory PAC price (local Brazilian cost) | W37: 4.247 | X37: 85044030 | Y37: 12.8x3.8x9.5 | Z37: Exact PN match in item catalog (17FH37A6) | AA37: High
A38: 41A240644P2 | B38: HORN MAGNET VALVE | C38: Controls (MCA, train control, er etc) | D38: TRAIN CONTROL | E38: 1 | H38: 461.70053 | I38: 578.13741 | J38: 578.13741 | K38: 2382.3747 | L38: 2983.189 | M38: 2382.3747 | O38: PAC (Brazil BRL) | P38: Brazilian factory PAC price (local Brazilian cost) | W38: 3.629 | X38: 84812090 | Y38: 8.4x3.35x7.5 | Z38: Exact PN match in item catalog (41A240644P2) | AA38: High
A39: 41A296352CMP387 | B39: ETHERNET CABLE | C39: Controls (MCA, train control, er etc) | D39: MCA | E39: 1 | H39: 413.22564 | I39: 517.43757 | J39: 517.43757 | K39: 2132.2443 | L39: 2669.9779 | M39: 2132.2443 | O39: PAC (Brazil BRL) | P39: Brazilian factory PAC price (local Brazilian cost) | R39: Wire/Cable | S39: Already nationalized (PAC) | T39: 2660.402 | U39: 2669.9779 | V39: Import is cheaper (by R$ 9.58) | W39: 0.227 | X39: 85444200 | Y39: 0x0x0 | Z39: Exact PN match in item catalog (41A296352CMP387) | AA39: High
A40: 41B511393P2 | B40: Battery Knife Switch | C40: Power | D40: POWER | E40: 1 | H40: 347.82993 | I40: 435.54962 | J40: 435.54962 | K40: 1794.8024 | L40: 2247.436 | M40: 1794.8024 | O40: PAC (Brazil BRL) | P40: Brazilian factory PAC price (local Brazilian cost) | W40: 4.445 | X40: 85365090 | Y40: 13.5x5.25x7 | Z40: Exact PN match in item catalog (41B511393P2) | AA40: High
...

Sheet GDT Integration and Assembly
A1: GDT Category | B1: Item / Service or Material Description | C1: Direct Cost BRL | D1: Direct Cost USD (@ 5.16) | E1: Gross Price BRL (Including PIS/COFINS and ICMS) | F1: Gross Price USD (Including PIS/COFINS and ICMS) | G1: Notes / Calculation Details
A2: Integration / Container Materials | B2: Container + enviromental Report | C2: 70000 | D2: 13565.891 | E2: 87653.393 | F2: 16987.092 | G2: Não incluso transporte do container
A3: Integration / Container Materials | B3: Pneumatics (tubulações, 14un mangueiras, 30un torneiras, conexões) | C3: 25000 | D3: 4844.9612 | E3: 31304.783 | F3: 6066.8185 | G3: Conexões pneumáticas gerais
A4: Integration / Container Materials | B4: Rack Electrical Connection | C4: 25000 | D4: 4844.9612 | E4: 31304.783 | F4: 6066.8185 | G4: Chicotes e passagem de cabos
A5: Integration / Container Materials | B5: Internal Electrical System (cabeamento, iluminação interna, 4un strobe, 6un steplights) | C5: 5000 | D5: 968.99225 | E5: 6260.9567 | F5: 1213.3637 | G5: Horn and headlight not needed
A6: Integration / Container Materials | B6: MU Connectors (4un), MU Jumpers (2un) | C6: 60000 | D6: 11627.907 | E6: 75131.48 | F6: 14560.364 | G6: Considerando eletrodutos e alongamento de cabeamento do container ao vagão
A7: Integration / Container Materials | B7: Air Conditioning, Inverter and Power | C7: 100000 | D7: 19379.845 | E7: 125219.13 | F7: 24267.274 | G7: Ar condicionado, inversor e potência para troca de calor
A8: Integration / Container Materials | B8: Container Thermal Insulation | C8: 100000 | D8: 19379.845 | E8: 125219.13 | F8: 24267.274 | G8: Isolamento térmico interno
A9: Integration / Container Materials | B9: Steel (railcar repair, ladder and access door) | C9: 12500 | D9: 2422.4806 | E9: 15652.392 | F9: 3033.4092 | G9: 25 reais por quilo
A10: Integration / Container Materials | B10: Painting and Lettering (Lettering) | C10: 5000 | D10: 968.99225 | E10: 6260.9567 | F10: 1213.3637 | G10: Não considerando pintar o vagão inteiro
A11: Integration / Container Materials | B11: Miscellaneous | C11: 10000 | D11: 1937.9845 | E11: 12521.913 | F11: 2426.7274 | G11: Insumos e materiais diversos
A12: Labor and Field Services | B12: Assembly and Integration Labor (Labor Cost) | C12: 122752 | D12: 23789.147 | E12: 153708.99 | F12: 29788.564 | G12: 1.096 horas (mecânica, elétrica, solda, pintura e campo) @ R$ 112/h
A13: Labor and Field Services | B13: Engineering / Project Design (NRE) | C13: 39424 | D13: 7640.3101 | E13: 49366.391 | F13: 9567.1301 | G13: 1 engenheiro + 1 projetista durante 1 mês
... A19: TOTAL GDT ROLLUP | B19: Total Integration, Adaptation and Services | C19: 707790.6 | D19: 137168.72 | E19: 886289.26 | F19: 171761.48 | G19: Sum of all additional materials and services from the rollup

Sheet Missing Items
A1: Part Number | B1: Description | C1: System | D1: Subsystem | E1: Status / Notes
A2: 41A296326CYP77 | B2: M12-A_ MALE_ 8-PIN_ STRAIGHT BSH | C2: SKID Assembly | D2: SKID (Skid) | E2: Quotation pending (no USD or BRL price)
A3: 41A296352PTP272 | B3: BC-PRECISION NAVIGATION MODULE | C3: SKID Assembly | D3: SKID (Skid) | E3: Quotation pending (no USD or BRL price)
A4: 41A296352PTP58 | B4: AY-DISPLAY CSX PTC DISPLAY | C4: SKID Assembly | D4: SKID (Skid) | E4: Quotation pending (no USD or BRL price)
A5: 41A296352PTP292 | B5: AX-POWER SUPPLY 13.6 V | C5: SKID Assembly | D5: SKID (Skid) | E5: Quotation pending (no USD or BRL price)
A6: MODEM ATT | B6: MODEM ATT | C6: SKID Assembly | D6: SKID (Skid) | E6: Quotation pending (no USD or BRL price)
A7: 84A237085AJP1 | B7: C-GoLIN EP_3 SMA_M2 CELL MODEM | C7: SKID Assembly | D7: Controls (MCA, train control, er etc) | E7: Quotation pending (no USD or BRL price)
A8: 17FL400B | B8: ST-DEVELOPER v19.4 | C8: SKID Assembly | D8: SKID (Skid) | E8: Quotation pending (no USD or BRL price)
A9: 41A296352CMP448 | B9: FB-DIGITAL RADIO MODULE | C9: SKID Assembly | D9: SKID (Skid) | E9: Quotation pending (no USD or BRL price)
A10: 41A296352PTP326 | B10: BH-WABTEC TRAIN MANAGEMENT COMPUTER _WTMC_ | C10: SKID Assembly | D10: SKID (Skid) | E10: Quotation pending (no USD or BRL price)
A11: 17FM711C3 | B11: H-PANEL DBM | C11: SKID Assembly | D11: SKID (Skid) | E11: Quotation pending (no USD or BRL price)
A12: 41A296352BCP9 | B12: N-HEAD OF TRAIN DEVICE | C12: SKID Assembly | D12: SKID (Skid) | E12: Quotation pending (no USD or BRL price)
... A22: PTC-FILT-NB-220-MIL-MF | B22: 220 Mhz PTC FILTER | C22: SKID Assembly | D22: later | E22: Quotation pending (no USD or BRL price)
B23: PTC Junction Box | C23: SKID Assembly | D23: SKID (Skid) | E23: Quotation pending (no USD or BRL price)
A24: 41A296352LUP15 | B24: 455 MHz Antenna (DPA, DPB, EOT ) | C24: SKID Assembly | D24: SKID (Skid) | E24: Quotation pending (no USD or BRL price)
A25: 84D749224G1 | B25: Power resistor | C25: SKID Assembly | D25: Battery Skid? | E25: Quotation pending (no USD or BRL price)

Sheet Freight Handoff
A1: US raw-cost freight handoff, sorted by US Total Cost (highest to lowest). Yellow = TP already included in source cost (rate not specified); Green = direct supplier, no TP; Blue = GET / TP to be confirmed; Uncolored = no TP status specified in the color review. PAC-sourced items are excluded.
A2: Part Number | B2: Description | C2: System | D2: SubSystem | E2: Quantity | F2: US Unit Cost (USD, no markup) | G2: US Total Cost (USD, no markup) | H2: Unit Weight (kg) | I2: Total Weight (kg) | J2: Dimensions (C x A x L, in) | K2: NCM | L2: Weight Confidence | M2: Notes | N2: Transfer Price Status
A3: 41A296352CMP437 | B3: Dual Processor Module (DPM)+ LXA (Distributed Power Radio) | C3: Controls (MCA, train control, er etc) | D3: LXA | E3: 1 | F3: 63100.819 | G3: 63100.819 | H3: 4.536 | I3: 4.536 | K3: 90328990 | L3: High | N3: Included in source cost (rate not specified)
A4: 84A222059P5 | B4: BATTERIES | C4: Power | D4: POWER | E4: 2 | F4: 15685.42 | G4: 31370.84 | H4: 1123.095 | I4: 2246.19 | L4: High | N4: Not applicable - direct supplier purchase
A5: 41A296352LUG24 | B5: CSX Antenna Enclosure Arrangement | C5: Connectivity | D5: ANTENNA KIT Master | E5: 1 | F5: 30000 | G5: 30000 | H5: 136.078 | I5: 136.078 | L5: High | N5: Not applicable - direct supplier purchase
A6: 37495P | B6: KIT ETMS VIRGIN TRAINS FEC EVO44 | C6: PTC | D6: PTC KIT MASTER | E6: 1 | F6: 28529 | G6: 28529 | H6: 45.359 | I6: 45.359 | L6: High | N6: Included in source cost (rate not specified)
A7: 84A215295P62 | B7: Pneumatic Brake Control System (Including lament and control portions) Includes EM EAB Control Functionality | C7: Air | D7: Fastbrake | E7: 1 | F7: 23409.1 | G7: 23409.1 | H7: 134.263 | I7: 134.263 | L7: High | N7: Included in source cost (rate not specified)
A8: 41A296352DNP37 | B8: RADIO PRAD PTC RADIO | C8: PTC | D8: PTC | E8: 1 | F8: 20000 | G8: 20000 | H8: 9.616 | I8: 9.616 | L8: High | N8: Not applicable - direct supplier purchase
A9: 17FM878A6 | B9: NIO 2.0 | C9: Controls (MCA, train control, er etc) | D9: MCA | E9: 3 | F9: 5176.9118 | G9: 15530.735 | H9: 8.618 | I9: 25.854 | L9: High | N9: Not applicable - direct supplier purchase
A10: L7000083-900 | B10: Wireless Communications Management Module, Gen 3 (WCM3)​ | C10: Controls (MCA, train control, er etc) | D10: TRAIN CONTROL | E10: 2 | F10: 5000 | G10: 10000 | H10: 2.268 | I10: 4.536 | L10: High | N10: Included in source cost (rate not specified)
A11: 84A237085AEP121 | B11: 8 Slot ACC Chassis for MCA w/ i7 HPEAP and SMM2 Cards | C11: Controls (MCA, train control, er etc) | D11: TRAIN CONTROL | E11: 1 | F11: 8000 | G11: 8000 | H11: 9.072 | I11: 9.072 | L11: High | N11: Included in source cost (rate not specified)
A12: 17KC108E28 | B12: MASTER CONTROLLER | C12: Controls (MCA, train control, er etc) | D12: TRAIN CONTROL | E12: 1 | F12: 5877.102 | G12: 5877.102 | H12: 25.855 | I12: 25.855 | L12: High | N12: GET / transfer price to be confirmed
A13: 84A215295P73 | B13: Air Brake Handle Assembly (AAR Console) | C13: Air | D13: Fastbrake | E13: 1 | F13: 5702.83 | G13: 5702.83 | H13: 7.938 | I13: 7.938 | L13: High | N13: Included in source cost (rate not specified)
A14: 17FM868B2 | B14: SNIO | C14: Controls (MCA, train control, er etc) | D14: MCA | E14: 1 | F14: 4150.9559 | G14: 4150.9559 | H14: 4.99 | I14: 4.99 | L14: High | N14: Not applicable - direct supplier purchase
A15: 41A296352DNP55 | B15: VOICE RADIO RITRON | C15: Connectivity | D15: VOICE RADIO | E15: 1 | F15: 3933 | G15: 3933 | H15: 7.575 | I15: 7.575 | L15: High | N15: Not applicable - direct supplier purchase
... A17: 41B546155P2 | B17: Horn | C17: Controls (MCA, train control, er etc) | D17: TRAIN CONTROL | E17: 1 | F17: 1891.99 | G17: 1891.99 | H17: 4.536 | I17: 4.536 | L17: High | N17: Not applicable - direct supplier purchase
B18: Ditchlight Control Box (SMART BOX-V3-DLC ) | C18: Controls (MCA, train control, er etc) | D18: TRAIN CONTROL | E18: 2 | F18: 800 | G18: 1600 | H18: 2.268 | I18: 4.536 | L18: High | N18: Not specified in color review
A19: 41D758679BJG16 84D704379AFG1 | B19: EC Part NumberL ASM | C19: Power | D19: Circuit Breaker | E19: 1 | F19: 1572.36 | G19: 1572.36 | H19: 4.99 | I19: 4.99 | J19: 20x3.5x25.5 | K19: 86079100 | L19: High | N19: GET / transfer price to be confirmed
B20: LED Ditch Light | C20: Controls (MCA, train control, er etc) | D20: TRAIN CONTROL | E20: 4 | F20: 375 | G20: 1500 | H20: 0.907 | I20: 3.628 | L20: High | N20: Not specified in color review
A21: 84A215295P3 | B21: POU-to-Handle cable 18' length | C21: Air | D21: Fastbrake | E21: 1 | F21: 1036.89 | G21: 1036.89 | H21: 1.247 | I21: 1.247 | L21: Medium | M21: Weight is an estimate (similar item) | N21: Included in source cost (rate not specified)
A22: RCCR-RMTCBL-RA-CUSTOM | B22: VOICE RADIO RITRON CABLE,REMOTE,RR-225/XXX, RCCR,RIGHT ANGLE,19-PIN,FLAME RETARDANT | C22: Connectivity | D22: VOICE RADIO | E22: 1 | F22: 761 | G22: 761 | M22: Weight not found - needs supplier data | N22: Not applicable - direct supplier purchase
A23: 41A296352PTP306/41A296352PTP122 | B23: Assembled Air Manifold (Contains 3 pressure sensors mounted in appropriate locations on Air Manifold.) | C23: PTC | D23: PTC | E23: 1 | F23: 595.7889 | G23: 595.7889 | H23: 5.897 | I23: 5.897 | K23: 85381000 | L23: Medium | M23: Weight is an estimate (similar item) | N23: Included in source cost (rate not specified)
A24: 32447P | B24: ASY CABLE WHEEL TACH AC EVO/SD70 ACE | C24: PTC | D24: PTC | E24: 1 | F24: 411.22 | G24: 411.22 | M24: Weight not found - needs supplier data | N24: Included in source cost (rate not specified)
A25: 41A296352PTP10/319/34 | B25: VALVE Part NumberEUMATIC NC/CO (Penalty Magnet Valve) Graham-White 812-142 | C25: PTC | D25: PTC | E25: 1 | F25: 404.6239 | G25: 404.6239 | M25: Weight not found - needs supplier data | N25: Included in source cost (rate not specified)
A26: 84A231123CSP30 | B26: Axle Tac - WRE Part Number: 29266P | C26: PTC | D26: PTC | E26: 1 | F26: 205 | G26: 205 | M26: Weight not found - needs supplier data | N26: Not specified in color review
A27: 84A207079ABP1 | B27: 41A313392DCP18 alternative 300" / | C27: Controls (MCA, train control, er etc) | D27: Wiring | E27: 25 | F27: 8.118 | G27: 202.95 | H27: 0.227 | I27: 5.675 | J27: 24x20x24 | K27: 85446000 | L27: High | N27: Not specified in color review
A28: 84A201850P4 | B28: ENGINE CONTROL SWITCH | C28: Controls (MCA, train control, er etc) | D28: TRAIN CONTROL | E28: 1 | F28: 171.544 | G28: 171.544 | M28: Weight not found - needs supplier data | N28: Not specified in color review
A29: RCCR-PWRCBL | B29: CABLE, PWR, 72V,RA,6.5FT (78").,RR-070,RCCR | C29: Connectivity | D29: VOICE RADIO | E29: 1 | F29: 159 | G29: 159 | M29: Weight not found - needs supplier data | N29: Not specified in color review
A30: 41A216641AMP126 | B30: NIO1D CONNECTOR BACKSHELL | C30: Controls (MCA, train control, er etc) | D30: Wiring | E30: 3 | F30: 29.9096 | G30: 89.7288 | H30: 0 | I30: 0 | J30: 0x0x0 | L30: High | N30: Not specified in color review
A31: 17 pin MS3106-20-29F | B31: Head of Train Device - Padom - J2 Connector | C31: Controls (MCA, train control, er etc) | D31: Wiring | E31: 1 | F31: 79.83 | G31: 79.83 | M31: Weight not found - needs supplier data | N31: Not specified in color review
A32: 41A216641AMP125 | B32: NIO1A CONNECTOR BACKSHELL | C32: Controls (MCA, train control, er etc) | D32: Wiring | E32: 3 | F32: 24.1998 | G32: 72.5994 | H32: 0.005 | I32: 0.015 | J32: 0x0x0 | L32: High | N32: Not specified in color review
A33: 5088-7000-P4611-0000000-ND‎ | B33: POE Power Connector on SMM2 (M12 FEMALE 0 L-CODED FIELD-WIREA) | C33: Controls (MCA, train control, er etc) | D33: TRAIN CONTROL | E33: 1 | F33: 72.41 | G33: 72.41 | M33: Weight not found - needs supplier data | N33: Not specified in color review
A34: 41A296352PTP67 | B34: CABLE CSX 12V P WR CBL | C34: Controls (MCA, train control, er etc) | D34: MCA | E34: 1 | F34: 71.94 | G34: 71.94 | M34: Weight not found - needs supplier data | N34: Not specified in color review
A35: 41A296352PTP69 | B35: CABLE CSX 74V P WR CBL | C35: Controls (MCA, train control, er etc) | D35: MCA | E35: 1 | F35: 71.94 | G35: 71.94 | M35: Weight not found - needs supplier data | N35: Not specified in color review
A36: 41A216641AMP93 | B36: NIO1E CONNECTOR | C36: Controls (MCA, train control, er etc) | D36: Wiring | E36: 3 | F36: 23.9499 | G36: 71.8497 | H36: 0.054 | I36: 0.162 | J36: 0x0x0 | L36: High | N36: Not specified in color review
A37: 41A216641AMP103 | B37: NIO1D CONNECTOR | C37: Controls (MCA, train control, er etc) | D37: Wiring | E37: 3 | F37: 21.2198 | G37: 63.6594 | H37: 0.045 | I37: 0.135 | J37: 1.5x1x1.5 | L37: High | N37: Not specified in color review
A38: 16246P | B38: Flexi-Axle - WRE Part Number: 16246P | C38: PTC | D38: PTC | E38: 1 | F38: 59.75 | G38: 59.75 | M38: Weight not found - needs supplier data | N38: Not specified in color review
A39: 41A216641AMP99 | B39: NIO1B CONNECTOR | C39: Controls (MCA, train control, er etc) | D39: Wiring | E39: 3 | F39: 19.67 | G39: 59.01 | H39: 0 | I39: 0 | J39: 0x0x0 | L39: High | N39: Not specified in color review
A40: 41A216641AMP123 | B40: NIO1F CONNECTOR BACKSHELL | C40: Controls (MCA, train control, er etc) | D40: Wiring | E40: 3 | F40: 19.5574 | G40: 58.6722 | H40: 0.02 | I40: 0.06 | J40: 0x0x0 | L40: High | N40: Not specified in color review
A41: 41A216641AMP100 | B41: NIO1C CONNECTOR | C41: Controls (MCA, train control, er etc) | D41: Wiring | E41: 3 | F41: 19.173 | G41: 57.519 | H41: 0 | I41: 0 | J41: 0x0x0 | L41: High | N41: Not specified in color review
...
